Workbook

Sheet Overview
A1: Banking Database — Excel Analysis & Power BI Dataset
A4: Key Figures (live)
A5: Customers | B5: Accounts | C5: Total Balance | D5: Transactions | E5: Loans | F5: Cards
A6: =COUNTA(CUSTOMERS!$A$2:$A$61) -> 60 | B6: =COUNTA(ACCOUNTS!$A$2:$A$83) -> 82 | C6: =SUM(ACCOUNTS!$D$2:$D$83) -> 1554450 | D6: =COUNTA(TRANSACTIONS!$A$2:$A$81) -> 80 | E6: =COUNTA(LOANS!$A$2:$A$61) -> 60 | F6: =COUNTA(CARDS!$A$2:$A$61) -> 60
A8: Data Quality Status
A9: Overall result of all validation checks: | E9: =IF(COUNTIF(Data_Quality!$D:$D,"FAIL")+COUNTIF(Data_Quality!$F:$F,"FAIL")=0,"ALL CHECKS PASSED","REVIEW NEEDED") -> ALL CHECKS PASSED
A11: Workbook Contents
A12: Dashboard | C12: Six charts summarising balances, accounts, transactions, loans and cards.
A13: 1–6 Analysis sheets | C13: SQL Part-1..6 results rebuilt as live COUNTIF / SUMIF / AVERAGEIF formulas.
A14: Pivot_Tables | C14: Formula-driven cross-tabs (accounts, loans, transactions).
A15: Data_Quality | C15: Row counts, duplicate-key, missing-value, referential-integrity & domain checks.
A16: Raw tables (14) | C16: BRANCHES … AUDIT_LOG — each an Excel Table (tbl_*), the Power BI source.
A18: Power BI Preparation
A19: • All 14 raw tables are clean Excel Tables (tbl_BRANCHES … tbl_AUDIT_LOG): one header row, typed columns, no blanks in keys.
A20: • Load with Power BI → Get Data → Excel → pick the tbl_* tables (not the analysis/pivot sheets).
A21: • Model relationships (star schema): BRANCHES 1—* CUSTOMERS 1—* ACCOUNTS 1—* TRANSACTIONS / CARDS / FEES / TRANSFERS / STANDING_ORDERS.
A22: • CUSTOMERS 1—* LOANS 1—* LOAN_PAYMENTS; CUSTOMERS 1—* BENEFICIARIES; BRANCHES 1—* EMPLOYEES / ATM_MACHINES.
A23: • ACCOUNTS & LOANS include derived branch_id / branch_name (green headers) so branch metrics work without extra joins.
A24: • Date columns are real dates — add a Date dimension in Power BI for time intelligence.
A26: Legend
B27: Blue header | C27: raw / analysis column
B28: Green header | C28: derived column (added for Power BI)
B29: Green cell | C29: check passed
B30: Red cell | C30: check failed
B31: Yellow cell | C31: expected / review

Sheet Dashboard
A1: Banking Analytics Dashboard

Sheet 1_Customer_Analysis
A1: 1 • Customer Analysis
A2: Live formulas referencing the raw CUSTOMERS / BRANCHES sheets.
A4: TOTAL CUSTOMERS | C4: CITIES | E4: BRANCHES USED
A5: =COUNTA(CUSTOMERS!$A$2:$A$61) -> 60 | C5: =SUMPRODUCT(1/COUNTIF(CUSTOMERS!$F$2:$F$61,CUSTOMERS!$F$2:$F$61)) -> 24 | E5: =SUMPRODUCT(1/COUNTIF(CUSTOMERS!$H$2:$H$61,CUSTOMERS!$H$2:$H$61)) -> 25
A7: 1.2 Customers by City | D7: 1.3 Customers by Branch (all branches, LEFT JOIN) | G7: 1.4 Monthly Registrations
A8: City | B8: Customers | D8: Branch | E8: Customers | G8: Month | H8: New Customers
A9: New York | B9: =COUNTIF(CUSTOMERS!$F$2:$F$61,A9) -> 6 | D9: Bay Branch | E9: =COUNTIF(CUSTOMERS!$H$2:$H$61,11) -> 3 | G9: 2017-08 | H9: =COUNTIFS(CUSTOMERS!$G$2:$G$61,">="&DATE(2017,8,1),CUSTOMERS!$G$2:$G$61,"<"&DATE(2017,9,1)) -> 1
A10: Miami | B10: =COUNTIF(CUSTOMERS!$F$2:$F$61,A10) -> 4 | D10: NorthWest Branch | E10: =COUNTIF(CUSTOMERS!$H$2:$H$61,8) -> 4 | G10: 2018-03 | H10: =COUNTIFS(CUSTOMERS!$G$2:$G$61,">="&DATE(2018,3,1),CUSTOMERS!$G$2:$G$61,"<"&DATE(2018,4,1)) -> 1
A11: Dallas | B11: =COUNTIF(CUSTOMERS!$F$2:$F$61,A11) -> 4 | D11: North Branch | E11: =COUNTIF(CUSTOMERS!$H$2:$H$61,4) -> 3 | G11: 2018-05 | H11: =COUNTIFS(CUSTOMERS!$G$2:$G$61,">="&DATE(2018,5,1),CUSTOMERS!$G$2:$G$61,"<"&DATE(2018,6,1)) -> 1
A12: Seattle | B12: =COUNTIF(CUSTOMERS!$F$2:$F$61,A12) -> 4 | D12: South Branch | E12: =COUNTIF(CUSTOMERS!$H$2:$H$61,6) -> 4 | G12: 2018-06 | H12: =COUNTIFS(CUSTOMERS!$G$2:$G$61,">="&DATE(2018,6,1),CUSTOMERS!$G$2:$G$61,"<"&DATE(2018,7,1)) -> 1
A13: Boston | B13: =COUNTIF(CUSTOMERS!$F$2:$F$61,A13) -> 4 | D13: Harbor Branch | E13: =COUNTIF(CUSTOMERS!$H$2:$H$61,9) -> 4 | G13: 2018-07 | H13: =COUNTIFS(CUSTOMERS!$G$2:$G$61,">="&DATE(2018,7,1),CUSTOMERS!$G$2:$G$61,"<"&DATE(2018,8,1)) -> 1
A14: Denver | B14: =COUNTIF(CUSTOMERS!$F$2:$F$61,A14) -> 4 | D14: Midtown Branch | E14: =COUNTIF(CUSTOMERS!$H$2:$H$61,14) -> 3 | G14: 2018-08 | H14: =COUNTIFS(CUSTOMERS!$G$2:$G$61,">="&DATE(2018,8,1),CUSTOMERS!$G$2:$G$61,"<"&DATE(2018,9,1)) -> 1
A15: Los Angeles | B15: =COUNTIF(CUSTOMERS!$F$2:$F$61,A15) -> 3 | D15: Riverside Branch | E15: =COUNTIF(CUSTOMERS!$H$2:$H$61,12) -> 3 | G15: 2018-11 | H15: =COUNTIFS(CUSTOMERS!$G$2:$G$61,">="&DATE(2018,11,1),CUSTOMERS!$G$2:$G$61,"<"&DATE(2018,12,1)) -> 1
A16: Chicago | B16: =COUNTIF(CUSTOMERS!$F$2:$F$61,A16) -> 3 | D16: Sixth Street Branch | E16: =COUNTIF(CUSTOMERS!$H$2:$H$61,32) -> 1 | G16: 2018-12 | H16: =COUNTIFS(CUSTOMERS!$G$2:$G$61,">="&DATE(2018,12,1),CUSTOMERS!$G$2:$G$61,"<"&DATE(2019,1,1)) -> 1
A17: Houston | B17: =COUNTIF(CUSTOMERS!$F$2:$F$61,A17) -> 3 | D17: Downtown Branch | E17: =COUNTIF(CUSTOMERS!$H$2:$H$61,2) -> 3 | G17: 2019-01 | H17: =COUNTIFS(CUSTOMERS!$G$2:$G$61,">="&DATE(2019,1,1),CUSTOMERS!$G$2:$G$61,"<"&DATE(2019,2,1)) -> 1
A18: San Francisco | B18: =COUNTIF(CUSTOMERS!$F$2:$F$61,A18) -> 3 | D18: Central Branch | E18: =COUNTIF(CUSTOMERS!$H$2:$H$61,7) -> 4 | G18: 2019-02 | H18: =COUNTIFS(CUSTOMERS!$G$2:$G$61,">="&DATE(2019,2,1),CUSTOMERS!$G$2:$G$61,"<"&DATE(2019,3,1)) -> 1
A19: Phoenix | B19: =COUNTIF(CUSTOMERS!$F$2:$F$61,A19) -> 3 | D19: Main Branch | E19: =COUNTIF(CUSTOMERS!$H$2:$H$61,1) -> 3 | G19: 2019-03 | H19: =COUNTIFS(CUSTOMERS!$G$2:$G$61,">="&DATE(2019,3,1),CUSTOMERS!$G$2:$G$61,"<"&DATE(2019,4,1)) -> 1
A20: Philadelphia | B20: =COUNTIF(CUSTOMERS!$F$2:$F$61,A20) -> 3 | D20: Metro Branch | E20: =COUNTIF(CUSTOMERS!$H$2:$H$61,13) -> 3 | G20: 2019-04 | H20: =COUNTIFS(CUSTOMERS!$G$2:$G$61,">="&DATE(2019,4,1),CUSTOMERS!$G$2:$G$61,"<"&DATE(2019,5,1)) -> 2
A21: Atlanta | B21: =COUNTIF(CUSTOMERS!$F$2:$F$61,A21) -> 3 | D21: Uptown Branch | E21: =COUNTIF(CUSTOMERS!$H$2:$H$61,35) -> 1 | G21: 2019-07 | H21: =COUNTIFS(CUSTOMERS!$G$2:$G$61,">="&DATE(2019,7,1),CUSTOMERS!$G$2:$G$61,"<"&DATE(2019,8,1)) -> 1
A22: Portland | B22: =COUNTIF(CUSTOMERS!$F$2:$F$61,A22) -> 3 | D22: Research Branch | E22: =COUNTIF(CUSTOMERS!$H$2:$H$61,38) -> 1 | G22: 2019-09 | H22: =COUNTIFS(CUSTOMERS!$G$2:$G$61,">="&DATE(2019,9,1),CUSTOMERS!$G$2:$G$61,"<"&DATE(2019,10,1)) -> 1
A23: Las Vegas | B23: =COUNTIF(CUSTOMERS!$F$2:$F$61,A23) -> 1 | D23: West Branch | E23: =COUNTIF(CUSTOMERS!$H$2:$H$61,3) -> 3 | G23: 2019-10 | H23: =COUNTIFS(CUSTOMERS!$G$2:$G$61,">="&DATE(2019,10,1),CUSTOMERS!$G$2:$G$61,"<"&DATE(2019,11,1)) -> 2
A24: Nashville | B24: =COUNTIF(CUSTOMERS!$F$2:$F$61,A24) -> 1 | D24: Strip Branch | E24: =COUNTIF(CUSTOMERS!$H$2:$H$61,30) -> 1 | G24: 2019-11 | H24: =COUNTIFS(CUSTOMERS!$G$2:$G$61,">="&DATE(2019,11,1),CUSTOMERS!$G$2:$G$61,"<"&DATE(2019,12,1)) -> 1
A25: Austin | B25: =COUNTIF(CUSTOMERS!$F$2:$F$61,A25) -> 1 | D25: Garden Branch | E25: =COUNTIF(CUSTOMERS!$H$2:$H$61,15) -> 3 | G25: 2019-12 | H25: =COUNTIFS(CUSTOMERS!$G$2:$G$61,">="&DATE(2019,12,1),CUSTOMERS!$G$2:$G$61,"<"&DATE(2020,1,1)) -> 1
A26: San Diego | B26: =COUNTIF(CUSTOMERS!$F$2:$F$61,A26) -> 1 | D26: Lakeside Branch | E26: =COUNTIF(CUSTOMERS!$H$2:$H$61,10) -> 4 | G26: 2020-01 | H26: =COUNTIFS(CUSTOMERS!$G$2:$G$61,">="&DATE(2020,1,1),CUSTOMERS!$G$2:$G$61,"<"&DATE(2020,2,1)) -> 1
A27: Detroit | B27: =COUNTIF(CUSTOMERS!$F$2:$F$61,A27) -> 1 | D27: Midtown Branch | E27: =COUNTIF(CUSTOMERS!$H$2:$H$61,34) -> 1 | G27: 2020-02 | H27: =COUNTIFS(CUSTOMERS!$G$2:$G$61,">="&DATE(2020,2,1),CUSTOMERS!$G$2:$G$61,"<"&DATE(2020,3,1)) -> 1
A28: Minneapolis | B28: =COUNTIF(CUSTOMERS!$F$2:$F$61,A28) -> 1 | D28: Broadway Branch | E28: =COUNTIF(CUSTOMERS!$H$2:$H$61,31) -> 1 | G28: 2020-03 | H28: =COUNTIFS(CUSTOMERS!$G$2:$G$61,">="&DATE(2020,3,1),CUSTOMERS!$G$2:$G$61,"<"&DATE(2020,4,1)) -> 1
A29: St. Louis | B29: =COUNTIF(CUSTOMERS!$F$2:$F$61,A29) -> 1 | D29: Inner Harbor Branch | E29: =COUNTIF(CUSTOMERS!$H$2:$H$61,37) -> 1 | G29: 2020-04 | H29: =COUNTIFS(CUSTOMERS!$G$2:$G$61,">="&DATE(2020,4,1),CUSTOMERS!$G$2:$G$61,"<"&DATE(2020,5,1)) -> 1
A30: Baltimore | B30: =COUNTIF(CUSTOMERS!$F$2:$F$61,A30) -> 1 | D30: Gaslamp Branch | E30: =COUNTIF(CUSTOMERS!$H$2:$H$61,33) -> 1 | G30: 2020-05 | H30: =COUNTIFS(CUSTOMERS!$G$2:$G$61,">="&DATE(2020,5,1),CUSTOMERS!$G$2:$G$61,"<"&DATE(2020,6,1)) -> 1
A31: Raleigh | B31: =COUNTIF(CUSTOMERS!$F$2:$F$61,A31) -> 1 | D31: Uptown Branch | E31: =COUNTIF(CUSTOMERS!$H$2:$H$61,39) -> 1 | G31: 2020-06 | H31: =COUNTIFS(CUSTOMERS!$G$2:$G$61,">="&DATE(2020,6,1),CUSTOMERS!$G$2:$G$61,"<"&DATE(2020,7,1)) -> 2
A32: Charlotte | B32: =COUNTIF(CUSTOMERS!$F$2:$F$61,A32) -> 1 | D32: Gateway Branch | E32: =COUNTIF(CUSTOMERS!$H$2:$H$61,36) -> 1 | G32: 2020-07 | H32: =COUNTIFS(CUSTOMERS!$G$2:$G$61,">="&DATE(2020,7,1),CUSTOMERS!$G$2:$G$61,"<"&DATE(2020,8,1)) -> 1
D33: East Branch | E33: =COUNTIF(CUSTOMERS!$H$2:$H$61,5) -> 3 | G33: 2020-08 | H33: =COUNTIFS(CUSTOMERS!$G$2:$G$61,">="&DATE(2020,8,1),CUSTOMERS!$G$2:$G$61,"<"&DATE(2020,9,1)) -> 1
D34: East Side Branch | E34: =COUNTIF(CUSTOMERS!$H$2:$H$61,16) -> 0 | G34: 2020-09 | H34: =COUNTIFS(CUSTOMERS!$G$2:$G$61,">="&DATE(2020,9,1),CUSTOMERS!$G$2:$G$61,"<"&DATE(2020,10,1)) -> 2
D35: Sunset Branch | E35: =COUNTIF(CUSTOMERS!$H$2:$H$61,17) -> 0 | G35: 2020-10 | H35: =COUNTIFS(CUSTOMERS!$G$2:$G$61,">="&DATE(2020,10,1),CUSTOMERS!$G$2:$G$61,"<"&DATE(2020,11,1)) -> 1
D36: Midway Branch | E36: =COUNTIF(CUSTOMERS!$H$2:$H$61,18) -> 0 | G36: 2020-11 | H36: =COUNTIFS(CUSTOMERS!$G$2:$G$61,">="&DATE(2020,11,1),CUSTOMERS!$G$2:$G$61,"<"&DATE(2020,12,1)) -> 2
D37: River Oaks Branch | E37: =COUNTIF(CUSTOMERS!$H$2:$H$61,19) -> 0 | G37: 2021-01 | H37: =COUNTIFS(CUSTOMERS!$G$2:$G$61,">="&DATE(2021,1,1),CUSTOMERS!$G$2:$G$61,"<"&DATE(2021,2,1)) -> 1
D38: Coconut Grove Branch | E38: =COUNTIF(CUSTOMERS!$H$2:$H$61,20) -> 0 | G38: 2021-02 | H38: =COUNTIFS(CUSTOMERS!$G$2:$G$61,">="&DATE(2021,2,1),CUSTOMERS!$G$2:$G$61,"<"&DATE(2021,3,1)) -> 1
D39: Uptown Branch | E39: =COUNTIF(CUSTOMERS!$H$2:$H$61,21) -> 0 | G39: 2021-03 | H39: =COUNTIFS(CUSTOMERS!$G$2:$G$61,">="&DATE(2021,3,1),CUSTOMERS!$G$2:$G$61,"<"&DATE(2021,4,1)) -> 2
D40: Capitol Hill Branch | E40: =COUNTIF(CUSTOMERS!$H$2:$H$61,22) -> 0 | G40: 2021-05 | H40: =COUNTIFS(CUSTOMERS!$G$2:$G$61,">="&DATE(2021,5,1),CUSTOMERS!$G$2:$G$61,"<"&DATE(2021,6,1)) -> 2
D41: Back Bay Branch | E41: =COUNTIF(CUSTOMERS!$H$2:$H$61,23) -> 0 | G41: 2021-06 | H41: =COUNTIFS(CUSTOMERS!$G$2:$G$61,">="&DATE(2021,6,1),CUSTOMERS!$G$2:$G$61,"<"&DATE(2021,7,1)) -> 1
D42: Cherry Creek Branch | E42: =COUNTIF(CUSTOMERS!$H$2:$H$61,24) -> 0 | G42: 2021-07 | H42: =COUNTIFS(CUSTOMERS!$G$2:$G$61,">="&DATE(2021,7,1),CUSTOMERS!$G$2:$G$61,"<"&DATE(2021,8,1)) -> 2
...

Sheet 2_Account_Analysis
A1: 2 • Account Analysis
A4: TOTAL ACCOUNTS | C4: ACTIVE | E4: AVG ACTIVE BAL | G4: TOTAL BALANCE
A5: =COUNTA(ACCOUNTS!$A$2:$A$83) -> 82 | C5: =COUNTIF(ACCOUNTS!$F$2:$F$83,"ACTIVE") -> 81 | E5: =ROUND(AVERAGEIFS(ACCOUNTS!$D$2:$D$83,ACCOUNTS!$F$2:$F$83,"ACTIVE"),2) -> 19190.74 | G5: =SUM(ACCOUNTS!$D$2:$D$83) -> 1554450
A7: 2.1 Accounts by Status | E7: 2.2 Total Balance by Branch
A8: Status | B8: Accounts | E8: Branch | F8: Total Balance
A9: ACTIVE | B9: =COUNTIF(ACCOUNTS!$F$2:$F$83,A9) -> 81 | E9: Bay Branch | F9: =SUMIF(ACCOUNTS!$G$2:$G$83,11,ACCOUNTS!$D$2:$D$83) -> 184700
A10: CLOSED | B10: =COUNTIF(ACCOUNTS!$F$2:$F$83,A10) -> 1 | E10: NorthWest Branch | F10: =SUMIF(ACCOUNTS!$G$2:$G$83,8,ACCOUNTS!$D$2:$D$83) -> 151000
E11: North Branch | F11: =SUMIF(ACCOUNTS!$G$2:$G$83,4,ACCOUNTS!$D$2:$D$83) -> 126700
A12: 2.4 Savings vs Checking | E12: South Branch | F12: =SUMIF(ACCOUNTS!$G$2:$G$83,6,ACCOUNTS!$D$2:$D$83) -> 125200
A13: Type | B13: Accounts | C13: Total Balance | E13: Harbor Branch | F13: =SUMIF(ACCOUNTS!$G$2:$G$83,9,ACCOUNTS!$D$2:$D$83) -> 121500
A14: SAVINGS | B14: =COUNTIF(ACCOUNTS!$C$2:$C$83,A14) -> 45 | C14: =SUMIF(ACCOUNTS!$C$2:$C$83,A14,ACCOUNTS!$D$2:$D$83) -> 1400000 | E14: Midtown Branch | F14: =SUMIF(ACCOUNTS!$G$2:$G$83,14,ACCOUNTS!$D$2:$D$83) -> 106200
A15: CHECKING | B15: =COUNTIF(ACCOUNTS!$C$2:$C$83,A15) -> 37 | C15: =SUMIF(ACCOUNTS!$C$2:$C$83,A15,ACCOUNTS!$D$2:$D$83) -> 154450 | E15: Riverside Branch | F15: =SUMIF(ACCOUNTS!$G$2:$G$83,12,ACCOUNTS!$D$2:$D$83) -> 86000
E16: Sixth Street Branch | F16: =SUMIF(ACCOUNTS!$G$2:$G$83,32,ACCOUNTS!$D$2:$D$83) -> 84200
A17: 2.5 Top 10 Customers by Balance | E17: Downtown Branch | F17: =SUMIF(ACCOUNTS!$G$2:$G$83,2,ACCOUNTS!$D$2:$D$83) -> 83600
A18: Customer ID | B18: Customer Name | C18: Total Balance | E18: Central Branch | F18: =SUMIF(ACCOUNTS!$G$2:$G$83,7,ACCOUNTS!$D$2:$D$83) -> 77200
A19: 21 | B19: Lucas Scott | C19: =SUMIF(ACCOUNTS!$B$2:$B$83,A19,ACCOUNTS!$D$2:$D$83) -> 135000 | E19: Main Branch | F19: =SUMIF(ACCOUNTS!$G$2:$G$83,1,ACCOUNTS!$D$2:$D$83) -> 53700
A20: 15 | B20: William Lewis | C20: =SUMIF(ACCOUNTS!$B$2:$B$83,A20,ACCOUNTS!$D$2:$D$83) -> 100500 | E20: Metro Branch | F20: =SUMIF(ACCOUNTS!$G$2:$G$83,13,ACCOUNTS!$D$2:$D$83) -> 47200
A21: 53 | B21: Caleb Washington | C21: =SUMIF(ACCOUNTS!$B$2:$B$83,A21,ACCOUNTS!$D$2:$D$83) -> 84200 | E21: Uptown Branch | F21: =SUMIF(ACCOUNTS!$G$2:$G$83,35,ACCOUNTS!$D$2:$D$83) -> 44000
A22: 10 | B22: James Lee | C22: =SUMIF(ACCOUNTS!$B$2:$B$83,A22,ACCOUNTS!$D$2:$D$83) -> 72500 | E22: Research Branch | F22: =SUMIF(ACCOUNTS!$G$2:$G$83,38,ACCOUNTS!$D$2:$D$83) -> 42600
A23: 34 | B23: Elizabeth Evans | C23: =SUMIF(ACCOUNTS!$B$2:$B$83,A23,ACCOUNTS!$D$2:$D$83) -> 71000 | E23: West Branch | F23: =SUMIF(ACCOUNTS!$G$2:$G$83,3,ACCOUNTS!$D$2:$D$83) -> 37500
A24: 44 | B24: Aria Bell | C24: =SUMIF(ACCOUNTS!$B$2:$B$83,A24,ACCOUNTS!$D$2:$D$83) -> 66900 | E24: Strip Branch | F24: =SUMIF(ACCOUNTS!$G$2:$G$83,30,ACCOUNTS!$D$2:$D$83) -> 36800
A25: 27 | B25: Alexander Mitchell | C25: =SUMIF(ACCOUNTS!$B$2:$B$83,A25,ACCOUNTS!$D$2:$D$83) -> 64200 | E25: Garden Branch | F25: =SUMIF(ACCOUNTS!$G$2:$G$83,15,ACCOUNTS!$D$2:$D$83) -> 34800
A26: 13 | B26: Noah Harris | C26: =SUMIF(ACCOUNTS!$B$2:$B$83,A26,ACCOUNTS!$D$2:$D$83) -> 52200 | E26: Lakeside Branch | F26: =SUMIF(ACCOUNTS!$G$2:$G$83,10,ACCOUNTS!$D$2:$D$83) -> 30600
A27: 4 | B27: David Wilson | C27: =SUMIF(ACCOUNTS!$B$2:$B$83,A27,ACCOUNTS!$D$2:$D$83) -> 50000 | E27: Midtown Branch | F27: =SUMIF(ACCOUNTS!$G$2:$G$83,34,ACCOUNTS!$D$2:$D$83) -> 24400
A28: 31 | B28: Michael Phillips | C28: =SUMIF(ACCOUNTS!$B$2:$B$83,A28,ACCOUNTS!$D$2:$D$83) -> 49700 | E28: Broadway Branch | F28: =SUMIF(ACCOUNTS!$G$2:$G$83,31,ACCOUNTS!$D$2:$D$83) -> 15500
E29: Inner Harbor Branch | F29: =SUMIF(ACCOUNTS!$G$2:$G$83,37,ACCOUNTS!$D$2:$D$83) -> 13800
E30: Gaslamp Branch | F30: =SUMIF(ACCOUNTS!$G$2:$G$83,33,ACCOUNTS!$D$2:$D$83) -> 9300
E31: Uptown Branch | F31: =SUMIF(ACCOUNTS!$G$2:$G$83,39,ACCOUNTS!$D$2:$D$83) -> 8700
E32: Gateway Branch | F32: =SUMIF(ACCOUNTS!$G$2:$G$83,36,ACCOUNTS!$D$2:$D$83) -> 7100
E33: East Branch | F33: =SUMIF(ACCOUNTS!$G$2:$G$83,5,ACCOUNTS!$D$2:$D$83) -> 2150

Sheet 3_Transaction_Analysis
A1: 3 • Transaction Analysis
A4: TRANSACTIONS | C4: TOTAL VALUE | E4: AVG AMOUNT
A5: =COUNTA(TRANSACTIONS!$A$2:$A$81) -> 80 | C5: =SUM(TRANSACTIONS!$D$2:$D$81) -> 443900 | E5: =ROUND(AVERAGE(TRANSACTIONS!$D$2:$D$81),2) -> 5548.75
A7: 3.1 Monthly Volume | E7: 3.2 Deposits / Withdrawals / Transfers
A8: Month | B8: # Transactions | C8: Total Amount | E8: Type | F8: # Transactions | G8: Total Amount
A9: 2024-01 | B9: =COUNTIFS(TRANSACTIONS!$E$2:$E$81,">="&DATE(2024,1,1),TRANSACTIONS!$E$2:$E$81,"<"&DATE(2024,2,1)) -> 8 | C9: =SUMIFS(TRANSACTIONS!$D$2:$D$81,TRANSACTIONS!$E$2:$E$81,">="&DATE(2024,1,1),TRANSACTIONS!$E$2:$E$81,"<"&DATE(2024,2,1)) -> 20000 | E9: DEPOSIT | F9: =COUNTIF(TRANSACTIONS!$C$2:$C$81,E9) -> 39 | G9: =SUMIF(TRANSACTIONS!$C$2:$C$81,E9,TRANSACTIONS!$D$2:$D$81) -> 378000
A10: 2024-02 | B10: =COUNTIFS(TRANSACTIONS!$E$2:$E$81,">="&DATE(2024,2,1),TRANSACTIONS!$E$2:$E$81,"<"&DATE(2024,3,1)) -> 7 | C10: =SUMIFS(TRANSACTIONS!$D$2:$D$81,TRANSACTIONS!$E$2:$E$81,">="&DATE(2024,2,1),TRANSACTIONS!$E$2:$E$81,"<"&DATE(2024,3,1)) -> 33100 | E10: WITHDRAWAL | F10: =COUNTIF(TRANSACTIONS!$C$2:$C$81,E10) -> 31 | G10: =SUMIF(TRANSACTIONS!$C$2:$C$81,E10,TRANSACTIONS!$D$2:$D$81) -> 41900
A11: 2024-03 | B11: =COUNTIFS(TRANSACTIONS!$E$2:$E$81,">="&DATE(2024,3,1),TRANSACTIONS!$E$2:$E$81,"<"&DATE(2024,4,1)) -> 11 | C11: =SUMIFS(TRANSACTIONS!$D$2:$D$81,TRANSACTIONS!$E$2:$E$81,">="&DATE(2024,3,1),TRANSACTIONS!$E$2:$E$81,"<"&DATE(2024,4,1)) -> 73100 | E11: TRANSFER | F11: =COUNTIF(TRANSACTIONS!$C$2:$C$81,E11) -> 10 | G11: =SUMIF(TRANSACTIONS!$C$2:$C$81,E11,TRANSACTIONS!$D$2:$D$81) -> 24000
A12: 2024-04 | B12: =COUNTIFS(TRANSACTIONS!$E$2:$E$81,">="&DATE(2024,4,1),TRANSACTIONS!$E$2:$E$81,"<"&DATE(2024,5,1)) -> 12 | C12: =SUMIFS(TRANSACTIONS!$D$2:$D$81,TRANSACTIONS!$E$2:$E$81,">="&DATE(2024,4,1),TRANSACTIONS!$E$2:$E$81,"<"&DATE(2024,5,1)) -> 96400
A13: 2024-05 | B13: =COUNTIFS(TRANSACTIONS!$E$2:$E$81,">="&DATE(2024,5,1),TRANSACTIONS!$E$2:$E$81,"<"&DATE(2024,6,1)) -> 12 | C13: =SUMIFS(TRANSACTIONS!$D$2:$D$81,TRANSACTIONS!$E$2:$E$81,">="&DATE(2024,5,1),TRANSACTIONS!$E$2:$E$81,"<"&DATE(2024,6,1)) -> 60000 | E13: 3.3 Largest 10 Transactions
A14: 2024-06 | B14: =COUNTIFS(TRANSACTIONS!$E$2:$E$81,">="&DATE(2024,6,1),TRANSACTIONS!$E$2:$E$81,"<"&DATE(2024,7,1)) -> 12 | C14: =SUMIFS(TRANSACTIONS!$D$2:$D$81,TRANSACTIONS!$E$2:$E$81,">="&DATE(2024,6,1),TRANSACTIONS!$E$2:$E$81,"<"&DATE(2024,7,1)) -> 75200 | E14: Txn ID | F14: Account | G14: Amount | H14: Date
A15: 2024-07 | B15: =COUNTIFS(TRANSACTIONS!$E$2:$E$81,">="&DATE(2024,7,1),TRANSACTIONS!$E$2:$E$81,"<"&DATE(2024,8,1)) -> 12 | C15: =SUMIFS(TRANSACTIONS!$D$2:$D$81,TRANSACTIONS!$E$2:$E$81,">="&DATE(2024,7,1),TRANSACTIONS!$E$2:$E$81,"<"&DATE(2024,8,1)) -> 58300 | E15: 1033 | F15: 129 | G15: 50000 | H15: 45397
A16: 2024-08 | B16: =COUNTIFS(TRANSACTIONS!$E$2:$E$81,">="&DATE(2024,8,1),TRANSACTIONS!$E$2:$E$81,"<"&DATE(2024,9,1)) -> 6 | C16: =SUMIFS(TRANSACTIONS!$D$2:$D$81,TRANSACTIONS!$E$2:$E$81,">="&DATE(2024,8,1),TRANSACTIONS!$E$2:$E$81,"<"&DATE(2024,9,1)) -> 27800 | E16: 1023 | F16: 120 | G16: 30000 | H16: 45371
E17: 1054 | F17: 148 | G17: 25000 | H17: 45451
E18: 1071 | F18: 173 | G18: 25000 | H18: 45495
A19: 3.4 Most Active Accounts (Top 10) | E19: 1013 | F19: 111 | G19: 20000 | H19: 45337
A20: Account | B20: # Transactions | C20: Total Amount | E20: 1043 | F20: 138 | G20: 20000 | H20: 45422
A21: 101 | B21: =COUNTIF(TRANSACTIONS!$B$2:$B$81,A21) -> 2 | C21: =SUMIF(TRANSACTIONS!$B$2:$B$81,A21,TRANSACTIONS!$D$2:$D$81) -> 6200 | E21: 1059 | F21: 152 | G21: 18000 | H21: 45463
A22: 103 | B22: =COUNTIF(TRANSACTIONS!$B$2:$B$81,A22) -> 2 | C22: =SUMIF(TRANSACTIONS!$B$2:$B$81,A22,TRANSACTIONS!$D$2:$D$81) -> 2500 | E22: 1021 | F22: 118 | G22: 15000 | H22: 45366
A23: 111 | B23: =COUNTIF(TRANSACTIONS!$B$2:$B$81,A23) -> 2 | C23: =SUMIF(TRANSACTIONS!$B$2:$B$81,A23,TRANSACTIONS!$D$2:$D$81) -> 23000 | E23: 1075 | F23: 177 | G23: 12000 | H23: 45505
A24: 114 | B24: =COUNTIF(TRANSACTIONS!$B$2:$B$81,A24) -> 2 | C24: =SUMIF(TRANSACTIONS!$B$2:$B$81,A24,TRANSACTIONS!$D$2:$D$81) -> 9500 | E24: 1007 | F24: 105 | G24: 10000 | H24: 45313
A25: 120 | B25: =COUNTIF(TRANSACTIONS!$B$2:$B$81,A25) -> 2 | C25: =SUMIF(TRANSACTIONS!$B$2:$B$81,A25,TRANSACTIONS!$D$2:$D$81) -> 35000
A26: 129 | B26: =COUNTIF(TRANSACTIONS!$B$2:$B$81,A26) -> 2 | C26: =SUMIF(TRANSACTIONS!$B$2:$B$81,A26,TRANSACTIONS!$D$2:$D$81) -> 58000
A27: 138 | B27: =COUNTIF(TRANSACTIONS!$B$2:$B$81,A27) -> 2 | C27: =SUMIF(TRANSACTIONS!$B$2:$B$81,A27,TRANSACTIONS!$D$2:$D$81) -> 24000
A28: 148 | B28: =COUNTIF(TRANSACTIONS!$B$2:$B$81,A28) -> 2 | C28: =SUMIF(TRANSACTIONS!$B$2:$B$81,A28,TRANSACTIONS!$D$2:$D$81) -> 30000
A29: 169 | B29: =COUNTIF(TRANSACTIONS!$B$2:$B$81,A29) -> 2 | C29: =SUMIF(TRANSACTIONS!$B$2:$B$81,A29,TRANSACTIONS!$D$2:$D$81) -> 7000
A30: 102 | B30: =COUNTIF(TRANSACTIONS!$B$2:$B$81,A30) -> 1 | C30: =SUMIF(TRANSACTIONS!$B$2:$B$81,A30,TRANSACTIONS!$D$2:$D$81) -> 800

Sheet 4_Loan_Analysis
A1: 4 • Loan Analysis
A4: TOTAL LOANS | C4: ACTIVE | E4: PAID | G4: AVG RATE %
A5: =COUNTA(LOANS!$A$2:$A$61) -> 60 | C5: =COUNTIF(LOANS!$H$2:$H$61,"ACTIVE") -> 52 | E5: =COUNTIF(LOANS!$H$2:$H$61,"PAID") -> 8 | G5: =ROUND(AVERAGE(LOANS!$E$2:$E$61),2) -> 5.54
A7: 4.3 Loans by Type (count · total · avg amount · avg rate) | G7: 4.5 Loan Amount by Branch (via customer→branch)
A8: Loan Type | B8: # Loans | C8: Total Amount | D8: Avg Amount | E8: Avg Rate % | G8: Branch | H8: Total Loan Amount
A9: HOME | B9: =COUNTIF(LOANS!$C$2:$C$61,A9) -> 17 | C9: =SUMIF(LOANS!$C$2:$C$61,A9,LOANS!$D$2:$D$61) -> 3710000 | D9: =ROUND(AVERAGEIF(LOANS!$C$2:$C$61,A9,LOANS!$D$2:$D$61),2) -> 218235.29 | E9: =ROUND(AVERAGEIF(LOANS!$C$2:$C$61,A9,LOANS!$E$2:$E$61),2) -> 3.56 | G9: Bay Branch | H9: =SUMIF(LOANS!$I$2:$I$61,11,LOANS!$D$2:$D$61) -> 1090000
A10: BUSINESS | B10: =COUNTIF(LOANS!$C$2:$C$61,A10) -> 9 | C10: =SUMIF(LOANS!$C$2:$C$61,A10,LOANS!$D$2:$D$61) -> 2280000 | D10: =ROUND(AVERAGEIF(LOANS!$C$2:$C$61,A10,LOANS!$D$2:$D$61),2) -> 253333.33 | E10: =ROUND(AVERAGEIF(LOANS!$C$2:$C$61,A10,LOANS!$E$2:$E$61),2) -> 3.97 | G10: Harbor Branch | H10: =SUMIF(LOANS!$I$2:$I$61,9,LOANS!$D$2:$D$61) -> 775000
A11: CAR | B11: =COUNTIF(LOANS!$C$2:$C$61,A11) -> 18 | C11: =SUMIF(LOANS!$C$2:$C$61,A11,LOANS!$D$2:$D$61) -> 290000 | D11: =ROUND(AVERAGEIF(LOANS!$C$2:$C$61,A11,LOANS!$D$2:$D$61),2) -> 16111.11 | E11: =ROUND(AVERAGEIF(LOANS!$C$2:$C$61,A11,LOANS!$E$2:$E$61),2) -> 5.82 | G11: South Branch | H11: =SUMIF(LOANS!$I$2:$I$61,6,LOANS!$D$2:$D$61) -> 635000
A12: PERSONAL | B12: =COUNTIF(LOANS!$C$2:$C$61,A12) -> 16 | C12: =SUMIF(LOANS!$C$2:$C$61,A12,LOANS!$D$2:$D$61) -> 94000 | D12: =ROUND(AVERAGEIF(LOANS!$C$2:$C$61,A12,LOANS!$D$2:$D$61),2) -> 5875 | E12: =ROUND(AVERAGEIF(LOANS!$C$2:$C$61,A12,LOANS!$E$2:$E$61),2) -> 8.21 | G12: Midtown Branch | H12: =SUMIF(LOANS!$I$2:$I$61,14,LOANS!$D$2:$D$61) -> 635000
G13: North Branch | H13: =SUMIF(LOANS!$I$2:$I$61,4,LOANS!$D$2:$D$61) -> 480000
G14: Main Branch | H14: =SUMIF(LOANS!$I$2:$I$61,1,LOANS!$D$2:$D$61) -> 413000
G15: NorthWest Branch | H15: =SUMIF(LOANS!$I$2:$I$61,8,LOANS!$D$2:$D$61) -> 387500
G16: Sixth Street Branch | H16: =SUMIF(LOANS!$I$2:$I$61,32,LOANS!$D$2:$D$61) -> 350000
G17: Uptown Branch | H17: =SUMIF(LOANS!$I$2:$I$61,35,LOANS!$D$2:$D$61) -> 280000
G18: Strip Branch | H18: =SUMIF(LOANS!$I$2:$I$61,30,LOANS!$D$2:$D$61) -> 225000
G19: Metro Branch | H19: =SUMIF(LOANS!$I$2:$I$61,13,LOANS!$D$2:$D$61) -> 210500
G20: Research Branch | H20: =SUMIF(LOANS!$I$2:$I$61,38,LOANS!$D$2:$D$61) -> 195000
G21: Gateway Branch | H21: =SUMIF(LOANS!$I$2:$I$61,36,LOANS!$D$2:$D$61) -> 180000
G22: Central Branch | H22: =SUMIF(LOANS!$I$2:$I$61,7,LOANS!$D$2:$D$61) -> 150000
G23: Downtown Branch | H23: =SUMIF(LOANS!$I$2:$I$61,2,LOANS!$D$2:$D$61) -> 120500
G24: Riverside Branch | H24: =SUMIF(LOANS!$I$2:$I$61,12,LOANS!$D$2:$D$61) -> 54000
G25: Lakeside Branch | H25: =SUMIF(LOANS!$I$2:$I$61,10,LOANS!$D$2:$D$61) -> 44000
G26: West Branch | H26: =SUMIF(LOANS!$I$2:$I$61,3,LOANS!$D$2:$D$61) -> 36000
G27: Garden Branch | H27: =SUMIF(LOANS!$I$2:$I$61,15,LOANS!$D$2:$D$61) -> 31000
G28: East Branch | H28: =SUMIF(LOANS!$I$2:$I$61,5,LOANS!$D$2:$D$61) -> 23000
G29: Midtown Branch | H29: =SUMIF(LOANS!$I$2:$I$61,34,LOANS!$D$2:$D$61) -> 18500
G30: Broadway Branch | H30: =SUMIF(LOANS!$I$2:$I$61,31,LOANS!$D$2:$D$61) -> 16000
G31: Uptown Branch | H31: =SUMIF(LOANS!$I$2:$I$61,39,LOANS!$D$2:$D$61) -> 14500
G32: Inner Harbor Branch | H32: =SUMIF(LOANS!$I$2:$I$61,37,LOANS!$D$2:$D$61) -> 6000
G33: Gaslamp Branch | H33: =SUMIF(LOANS!$I$2:$I$61,33,LOANS!$D$2:$D$61) -> 4500

Sheet 5_Card_Analysis
A1: 5 • Card Analysis
A4: TOTAL CARDS | C4: ACTIVE | E4: EXPIRED | G4: BLOCKED
A5: =COUNTA(CARDS!$A$2:$A$61) -> 60 | C5: =COUNTIF(CARDS!$F$2:$F$61,"ACTIVE") -> 53 | E5: =COUNTIF(CARDS!$F$2:$F$61,"EXPIRED") -> 6 | G5: =COUNTIF(CARDS!$F$2:$F$61,"BLOCKED") -> 1
A7: 5.2 Cards by Type | D7: 5.1 / 5.3 Cards by Status
A8: Card Type | B8: # Cards | D8: Status | E8: # Cards
A9: DEBIT | B9: =COUNTIF(CARDS!$C$2:$C$61,A9) -> 38 | D9: ACTIVE | E9: =COUNTIF(CARDS!$F$2:$F$61,D9) -> 53
A10: CREDIT | B10: =COUNTIF(CARDS!$C$2:$C$61,A10) -> 22 | D10: EXPIRED | E10: =COUNTIF(CARDS!$F$2:$F$61,D10) -> 6
D11: BLOCKED | E11: =COUNTIF(CARDS!$F$2:$F$61,D11) -> 1

Sheet 6_Branch_Performance
A1: 6 • Branch Performance
A2: 6.1 customers · 6.2 employees · 6.3 accounts · 6.4 balance + rank. Ranked by total balance.
A4: Branch | B4: City | C4: Customers | D4: Employees | E4: Accounts | F4: Total Balance | G4: Rank
A5: Bay Branch | B5: San Francisco | C5: =COUNTIF(CUSTOMERS!$H$2:$H$61,11) -> 3 | D5: =COUNTIF(EMPLOYEES!$F$2:$F$61,11) -> 2 | E5: =COUNTIF(ACCOUNTS!$G$2:$G$83,11) -> 5 | F5: =SUMIF(ACCOUNTS!$G$2:$G$83,11,ACCOUNTS!$D$2:$D$83) -> 184700 | G5: =RANK(F5,$F$5:$F$64) -> 1
A6: NorthWest Branch | B6: Seattle | C6: =COUNTIF(CUSTOMERS!$H$2:$H$61,8) -> 4 | D6: =COUNTIF(EMPLOYEES!$F$2:$F$61,8) -> 2 | E6: =COUNTIF(ACCOUNTS!$G$2:$G$83,8) -> 5 | F6: =SUMIF(ACCOUNTS!$G$2:$G$83,8,ACCOUNTS!$D$2:$D$83) -> 151000 | G6: =RANK(F6,$F$5:$F$64) -> 2
A7: North Branch | B7: Chicago | C7: =COUNTIF(CUSTOMERS!$H$2:$H$61,4) -> 3 | D7: =COUNTIF(EMPLOYEES!$F$2:$F$61,4) -> 4 | E7: =COUNTIF(ACCOUNTS!$G$2:$G$83,4) -> 4 | F7: =SUMIF(ACCOUNTS!$G$2:$G$83,4,ACCOUNTS!$D$2:$D$83) -> 126700 | G7: =RANK(F7,$F$5:$F$64) -> 3
A8: South Branch | B8: Miami | C8: =COUNTIF(CUSTOMERS!$H$2:$H$61,6) -> 4 | D8: =COUNTIF(EMPLOYEES!$F$2:$F$61,6) -> 3 | E8: =COUNTIF(ACCOUNTS!$G$2:$G$83,6) -> 6 | F8: =SUMIF(ACCOUNTS!$G$2:$G$83,6,ACCOUNTS!$D$2:$D$83) -> 125200 | G8: =RANK(F8,$F$5:$F$64) -> 4
A9: Harbor Branch | B9: Boston | C9: =COUNTIF(CUSTOMERS!$H$2:$H$61,9) -> 4 | D9: =COUNTIF(EMPLOYEES!$F$2:$F$61,9) -> 2 | E9: =COUNTIF(ACCOUNTS!$G$2:$G$83,9) -> 5 | F9: =SUMIF(ACCOUNTS!$G$2:$G$83,9,ACCOUNTS!$D$2:$D$83) -> 121500 | G9: =RANK(F9,$F$5:$F$64) -> 5
A10: Midtown Branch | B10: Atlanta | C10: =COUNTIF(CUSTOMERS!$H$2:$H$61,14) -> 3 | D10: =COUNTIF(EMPLOYEES!$F$2:$F$61,14) -> 2 | E10: =COUNTIF(ACCOUNTS!$G$2:$G$83,14) -> 4 | F10: =SUMIF(ACCOUNTS!$G$2:$G$83,14,ACCOUNTS!$D$2:$D$83) -> 106200 | G10: =RANK(F10,$F$5:$F$64) -> 6
A11: Riverside Branch | B11: Phoenix | C11: =COUNTIF(CUSTOMERS!$H$2:$H$61,12) -> 3 | D11: =COUNTIF(EMPLOYEES!$F$2:$F$61,12) -> 2 | E11: =COUNTIF(ACCOUNTS!$G$2:$G$83,12) -> 4 | F11: =SUMIF(ACCOUNTS!$G$2:$G$83,12,ACCOUNTS!$D$2:$D$83) -> 86000 | G11: =RANK(F11,$F$5:$F$64) -> 7
A12: Sixth Street Branch | B12: Austin | C12: =COUNTIF(CUSTOMERS!$H$2:$H$61,32) -> 1 | D12: =COUNTIF(EMPLOYEES!$F$2:$F$61,32) -> 0 | E12: =COUNTIF(ACCOUNTS!$G$2:$G$83,32) -> 2 | F12: =SUMIF(ACCOUNTS!$G$2:$G$83,32,ACCOUNTS!$D$2:$D$83) -> 84200 | G12: =RANK(F12,$F$5:$F$64) -> 8
A13: Downtown Branch | B13: New York | C13: =COUNTIF(CUSTOMERS!$H$2:$H$61,2) -> 3 | D13: =COUNTIF(EMPLOYEES!$F$2:$F$61,2) -> 4 | E13: =COUNTIF(ACCOUNTS!$G$2:$G$83,2) -> 5 | F13: =SUMIF(ACCOUNTS!$G$2:$G$83,2,ACCOUNTS!$D$2:$D$83) -> 83600 | G13: =RANK(F13,$F$5:$F$64) -> 9
A14: Central Branch | B14: Dallas | C14: =COUNTIF(CUSTOMERS!$H$2:$H$61,7) -> 4 | D14: =COUNTIF(EMPLOYEES!$F$2:$F$61,7) -> 2 | E14: =COUNTIF(ACCOUNTS!$G$2:$G$83,7) -> 5 | F14: =SUMIF(ACCOUNTS!$G$2:$G$83,7,ACCOUNTS!$D$2:$D$83) -> 77200 | G14: =RANK(F14,$F$5:$F$64) -> 10
A15: Main Branch | B15: New York | C15: =COUNTIF(CUSTOMERS!$H$2:$H$61,1) -> 3 | D15: =COUNTIF(EMPLOYEES!$F$2:$F$61,1) -> 4 | E15: =COUNTIF(ACCOUNTS!$G$2:$G$83,1) -> 4 | F15: =SUMIF(ACCOUNTS!$G$2:$G$83,1,ACCOUNTS!$D$2:$D$83) -> 53700 | G15: =RANK(F15,$F$5:$F$64) -> 11
A16: Metro Branch | B16: Philadelphia | C16: =COUNTIF(CUSTOMERS!$H$2:$H$61,13) -> 3 | D16: =COUNTIF(EMPLOYEES!$F$2:$F$61,13) -> 2 | E16: =COUNTIF(ACCOUNTS!$G$2:$G$83,13) -> 4 | F16: =SUMIF(ACCOUNTS!$G$2:$G$83,13,ACCOUNTS!$D$2:$D$83) -> 47200 | G16: =RANK(F16,$F$5:$F$64) -> 12
A17: Uptown Branch | B17: Minneapolis | C17: =COUNTIF(CUSTOMERS!$H$2:$H$61,35) -> 1 | D17: =COUNTIF(EMPLOYEES!$F$2:$F$61,35) -> 0 | E17: =COUNTIF(ACCOUNTS!$G$2:$G$83,35) -> 1 | F17: =SUMIF(ACCOUNTS!$G$2:$G$83,35,ACCOUNTS!$D$2:$D$83) -> 44000 | G17: =RANK(F17,$F$5:$F$64) -> 13
A18: Research Branch | B18: Raleigh | C18: =COUNTIF(CUSTOMERS!$H$2:$H$61,38) -> 1 | D18: =COUNTIF(EMPLOYEES!$F$2:$F$61,38) -> 0 | E18: =COUNTIF(ACCOUNTS!$G$2:$G$83,38) -> 2 | F18: =SUMIF(ACCOUNTS!$G$2:$G$83,38,ACCOUNTS!$D$2:$D$83) -> 42600 | G18: =RANK(F18,$F$5:$F$64) -> 14
A19: West Branch | B19: Los Angeles | C19: =COUNTIF(CUSTOMERS!$H$2:$H$61,3) -> 3 | D19: =COUNTIF(EMPLOYEES!$F$2:$F$61,3) -> 4 | E19: =COUNTIF(ACCOUNTS!$G$2:$G$83,3) -> 4 | F19: =SUMIF(ACCOUNTS!$G$2:$G$83,3,ACCOUNTS!$D$2:$D$83) -> 37500 | G19: =RANK(F19,$F$5:$F$64) -> 15
A20: Strip Branch | B20: Las Vegas | C20: =COUNTIF(CUSTOMERS!$H$2:$H$61,30) -> 1 | D20: =COUNTIF(EMPLOYEES!$F$2:$F$61,30) -> 0 | E20: =COUNTIF(ACCOUNTS!$G$2:$G$83,30) -> 2 | F20: =SUMIF(ACCOUNTS!$G$2:$G$83,30,ACCOUNTS!$D$2:$D$83) -> 36800 | G20: =RANK(F20,$F$5:$F$64) -> 16
A21: Garden Branch | B21: Portland | C21: =COUNTIF(CUSTOMERS!$H$2:$H$61,15) -> 3 | D21: =COUNTIF(EMPLOYEES!$F$2:$F$61,15) -> 2 | E21: =COUNTIF(ACCOUNTS!$G$2:$G$83,15) -> 4 | F21: =SUMIF(ACCOUNTS!$G$2:$G$83,15,ACCOUNTS!$D$2:$D$83) -> 34800 | G21: =RANK(F21,$F$5:$F$64) -> 17
A22: Lakeside Branch | B22: Denver | C22: =COUNTIF(CUSTOMERS!$H$2:$H$61,10) -> 4 | D22: =COUNTIF(EMPLOYEES!$F$2:$F$61,10) -> 2 | E22: =COUNTIF(ACCOUNTS!$G$2:$G$83,10) -> 6 | F22: =SUMIF(ACCOUNTS!$G$2:$G$83,10,ACCOUNTS!$D$2:$D$83) -> 30600 | G22: =RANK(F22,$F$5:$F$64) -> 18
A23: Midtown Branch | B23: Detroit | C23: =COUNTIF(CUSTOMERS!$H$2:$H$61,34) -> 1 | D23: =COUNTIF(EMPLOYEES!$F$2:$F$61,34) -> 0 | E23: =COUNTIF(ACCOUNTS!$G$2:$G$83,34) -> 2 | F23: =SUMIF(ACCOUNTS!$G$2:$G$83,34,ACCOUNTS!$D$2:$D$83) -> 24400 | G23: =RANK(F23,$F$5:$F$64) -> 19
A24: Broadway Branch | B24: Nashville | C24: =COUNTIF(CUSTOMERS!$H$2:$H$61,31) -> 1 | D24: =COUNTIF(EMPLOYEES!$F$2:$F$61,31) -> 0 | E24: =COUNTIF(ACCOUNTS!$G$2:$G$83,31) -> 1 | F24: =SUMIF(ACCOUNTS!$G$2:$G$83,31,ACCOUNTS!$D$2:$D$83) -> 15500 | G24: =RANK(F24,$F$5:$F$64) -> 20
A25: Inner Harbor Branch | B25: Baltimore | C25: =COUNTIF(CUSTOMERS!$H$2:$H$61,37) -> 1 | D25: =COUNTIF(EMPLOYEES!$F$2:$F$61,37) -> 0 | E25: =COUNTIF(ACCOUNTS!$G$2:$G$83,37) -> 1 | F25: =SUMIF(ACCOUNTS!$G$2:$G$83,37,ACCOUNTS!$D$2:$D$83) -> 13800 | G25: =RANK(F25,$F$5:$F$64) -> 21
A26: Gaslamp Branch | B26: San Diego | C26: =COUNTIF(CUSTOMERS!$H$2:$H$61,33) -> 1 | D26: =COUNTIF(EMPLOYEES!$F$2:$F$61,33) -> 0 | E26: =COUNTIF(ACCOUNTS!$G$2:$G$83,33) -> 1 | F26: =SUMIF(ACCOUNTS!$G$2:$G$83,33,ACCOUNTS!$D$2:$D$83) -> 9300 | G26: =RANK(F26,$F$5:$F$64) -> 22
A27: Uptown Branch | B27: Charlotte | C27: =COUNTIF(CUSTOMERS!$H$2:$H$61,39) -> 1 | D27: =COUNTIF(EMPLOYEES!$F$2:$F$61,39) -> 0 | E27: =COUNTIF(ACCOUNTS!$G$2:$G$83,39) -> 1 | F27: =SUMIF(ACCOUNTS!$G$2:$G$83,39,ACCOUNTS!$D$2:$D$83) -> 8700 | G27: =RANK(F27,$F$5:$F$64) -> 23
A28: Gateway Branch | B28: St. Louis | C28: =COUNTIF(CUSTOMERS!$H$2:$H$61,36) -> 1 | D28: =COUNTIF(EMPLOYEES!$F$2:$F$61,36) -> 0 | E28: =COUNTIF(ACCOUNTS!$G$2:$G$83,36) -> 1 | F28: =SUMIF(ACCOUNTS!$G$2:$G$83,36,ACCOUNTS!$D$2:$D$83) -> 7100 | G28: =RANK(F28,$F$5:$F$64) -> 24
A29: East Branch | B29: Houston | C29: =COUNTIF(CUSTOMERS!$H$2:$H$61,5) -> 3 | D29: =COUNTIF(EMPLOYEES!$F$2:$F$61,5) -> 3 | E29: =COUNTIF(ACCOUNTS!$G$2:$G$83,5) -> 3 | F29: =SUMIF(ACCOUNTS!$G$2:$G$83,5,ACCOUNTS!$D$2:$D$83) -> 2150 | G29: =RANK(F29,$F$5:$F$64) -> 25
A30: East Side Branch | B30: New York | C30: =COUNTIF(CUSTOMERS!$H$2:$H$61,16) -> 0 | D30: =COUNTIF(EMPLOYEES!$F$2:$F$61,16) -> 2 | E30: =COUNTIF(ACCOUNTS!$G$2:$G$83,16) -> 0 | F30: =SUMIF(ACCOUNTS!$G$2:$G$83,16,ACCOUNTS!$D$2:$D$83) -> 0 | G30: =RANK(F30,$F$5:$F$64) -> 26
A31: Sunset Branch | B31: Los Angeles | C31: =COUNTIF(CUSTOMERS!$H$2:$H$61,17) -> 0 | D31: =COUNTIF(EMPLOYEES!$F$2:$F$61,17) -> 2 | E31: =COUNTIF(ACCOUNTS!$G$2:$G$83,17) -> 0 | F31: =SUMIF(ACCOUNTS!$G$2:$G$83,17,ACCOUNTS!$D$2:$D$83) -> 0 | G31: =RANK(F31,$F$5:$F$64) -> 26
A32: Midway Branch | B32: Chicago | C32: =COUNTIF(CUSTOMERS!$H$2:$H$61,18) -> 0 | D32: =COUNTIF(EMPLOYEES!$F$2:$F$61,18) -> 2 | E32: =COUNTIF(ACCOUNTS!$G$2:$G$83,18) -> 0 | F32: =SUMIF(ACCOUNTS!$G$2:$G$83,18,ACCOUNTS!$D$2:$D$83) -> 0 | G32: =RANK(F32,$F$5:$F$64) -> 26
A33: River Oaks Branch | B33: Houston | C33: =COUNTIF(CUSTOMERS!$H$2:$H$61,19) -> 0 | D33: =COUNTIF(EMPLOYEES!$F$2:$F$61,19) -> 2 | E33: =COUNTIF(ACCOUNTS!$G$2:$G$83,19) -> 0 | F33: =SUMIF(ACCOUNTS!$G$2:$G$83,19,ACCOUNTS!$D$2:$D$83) -> 0 | G33: =RANK(F33,$F$5:$F$64) -> 26
A34: Coconut Grove Branch | B34: Miami | C34: =COUNTIF(CUSTOMERS!$H$2:$H$61,20) -> 0 | D34: =COUNTIF(EMPLOYEES!$F$2:$F$61,20) -> 2 | E34: =COUNTIF(ACCOUNTS!$G$2:$G$83,20) -> 0 | F34: =SUMIF(ACCOUNTS!$G$2:$G$83,20,ACCOUNTS!$D$2:$D$83) -> 0 | G34: =RANK(F34,$F$5:$F$64) -> 26
A35: Uptown Branch | B35: Dallas | C35: =COUNTIF(CUSTOMERS!$H$2:$H$61,21) -> 0 | D35: =COUNTIF(EMPLOYEES!$F$2:$F$61,21) -> 2 | E35: =COUNTIF(ACCOUNTS!$G$2:$G$83,21) -> 0 | F35: =SUMIF(ACCOUNTS!$G$2:$G$83,21,ACCOUNTS!$D$2:$D$83) -> 0 | G35: =RANK(F35,$F$5:$F$64) -> 26
A36: Capitol Hill Branch | B36: Seattle | C36: =COUNTIF(CUSTOMERS!$H$2:$H$61,22) -> 0 | D36: =COUNTIF(EMPLOYEES!$F$2:$F$61,22) -> 2 | E36: =COUNTIF(ACCOUNTS!$G$2:$G$83,22) -> 0 | F36: =SUMIF(ACCOUNTS!$G$2:$G$83,22,ACCOUNTS!$D$2:$D$83) -> 0 | G36: =RANK(F36,$F$5:$F$64) -> 26
A37: Back Bay Branch | B37: Boston | C37: =COUNTIF(CUSTOMERS!$H$2:$H$61,23) -> 0 | D37: =COUNTIF(EMPLOYEES!$F$2:$F$61,23) -> 2 | E37: =COUNTIF(ACCOUNTS!$G$2:$G$83,23) -> 0 | F37: =SUMIF(ACCOUNTS!$G$2:$G$83,23,ACCOUNTS!$D$2:$D$83) -> 0 | G37: =RANK(F37,$F$5:$F$64) -> 26
A38: Cherry Creek Branch | B38: Denver | C38: =COUNTIF(CUSTOMERS!$H$2:$H$61,24) -> 0 | D38: =COUNTIF(EMPLOYEES!$F$2:$F$61,24) -> 2 | E38: =COUNTIF(ACCOUNTS!$G$2:$G$83,24) -> 0 | F38: =SUMIF(ACCOUNTS!$G$2:$G$83,24,ACCOUNTS!$D$2:$D$83) -> 0 | G38: =RANK(F38,$F$5:$F$64) -> 26
A39: Financial District | B39: San Francisco | C39: =COUNTIF(CUSTOMERS!$H$2:$H$61,25) -> 0 | D39: =COUNTIF(EMPLOYEES!$F$2:$F$61,25) -> 2 | E39: =COUNTIF(ACCOUNTS!$G$2:$G$83,25) -> 0 | F39: =SUMIF(ACCOUNTS!$G$2:$G$83,25,ACCOUNTS!$D$2:$D$83) -> 0 | G39: =RANK(F39,$F$5:$F$64) -> 26
A40: Scottsdale Branch | B40: Phoenix | C40: =COUNTIF(CUSTOMERS!$H$2:$H$61,26) -> 0 | D40: =COUNTIF(EMPLOYEES!$F$2:$F$61,26) -> 0 | E40: =COUNTIF(ACCOUNTS!$G$2:$G$83,26) -> 0 | F40: =SUMIF(ACCOUNTS!$G$2:$G$83,26,ACCOUNTS!$D$2:$D$83) -> 0 | G40: =RANK(F40,$F$5:$F$64) -> 26
A41: Center City Branch | B41: Philadelphia | C41: =COUNTIF(CUSTOMERS!$H$2:$H$61,27) -> 0 | D41: =COUNTIF(EMPLOYEES!$F$2:$F$61,27) -> 0 | E41: =COUNTIF(ACCOUNTS!$G$2:$G$83,27) -> 0 | F41: =SUMIF(ACCOUNTS!$G$2:$G$83,27,ACCOUNTS!$D$2:$D$83) -> 0 | G41: =RANK(F41,$F$5:$F$64) -> 26
...

Sheet Pivot_Tables
A1: Pivot Tables (formula-driven cross-tabs)
A2: Live SUMIFS/COUNTIFS matrices. Native Excel PivotTables can also be built one-click from the tbl_* tables on the raw sheets.
A4: Pivot 1 — Account Count by Branch × Type
A5: Branch | B5: SAVINGS | C5: CHECKING | D5: Total
A6: Main Branch | B6: =COUNTIFS(ACCOUNTS!$G$2:$G$83,1,ACCOUNTS!$C$2:$C$83,"SAVINGS") -> 3 | C6: =COUNTIFS(ACCOUNTS!$G$2:$G$83,1,ACCOUNTS!$C$2:$C$83,"CHECKING") -> 1 | D6: =B6+C6 -> 4
A7: Downtown Branch | B7: =COUNTIFS(ACCOUNTS!$G$2:$G$83,2,ACCOUNTS!$C$2:$C$83,"SAVINGS") -> 2 | C7: =COUNTIFS(ACCOUNTS!$G$2:$G$83,2,ACCOUNTS!$C$2:$C$83,"CHECKING") -> 3 | D7: =B7+C7 -> 5
A8: West Branch | B8: =COUNTIFS(ACCOUNTS!$G$2:$G$83,3,ACCOUNTS!$C$2:$C$83,"SAVINGS") -> 2 | C8: =COUNTIFS(ACCOUNTS!$G$2:$G$83,3,ACCOUNTS!$C$2:$C$83,"CHECKING") -> 2 | D8: =B8+C8 -> 4
A9: North Branch | B9: =COUNTIFS(ACCOUNTS!$G$2:$G$83,4,ACCOUNTS!$C$2:$C$83,"SAVINGS") -> 3 | C9: =COUNTIFS(ACCOUNTS!$G$2:$G$83,4,ACCOUNTS!$C$2:$C$83,"CHECKING") -> 1 | D9: =B9+C9 -> 4
A10: East Branch | B10: =COUNTIFS(ACCOUNTS!$G$2:$G$83,5,ACCOUNTS!$C$2:$C$83,"SAVINGS") -> 0 | C10: =COUNTIFS(ACCOUNTS!$G$2:$G$83,5,ACCOUNTS!$C$2:$C$83,"CHECKING") -> 3 | D10: =B10+C10 -> 3
A11: South Branch | B11: =COUNTIFS(ACCOUNTS!$G$2:$G$83,6,ACCOUNTS!$C$2:$C$83,"SAVINGS") -> 4 | C11: =COUNTIFS(ACCOUNTS!$G$2:$G$83,6,ACCOUNTS!$C$2:$C$83,"CHECKING") -> 2 | D11: =B11+C11 -> 6
A12: Central Branch | B12: =COUNTIFS(ACCOUNTS!$G$2:$G$83,7,ACCOUNTS!$C$2:$C$83,"SAVINGS") -> 2 | C12: =COUNTIFS(ACCOUNTS!$G$2:$G$83,7,ACCOUNTS!$C$2:$C$83,"CHECKING") -> 3 | D12: =B12+C12 -> 5
A13: NorthWest Branch | B13: =COUNTIFS(ACCOUNTS!$G$2:$G$83,8,ACCOUNTS!$C$2:$C$83,"SAVINGS") -> 3 | C13: =COUNTIFS(ACCOUNTS!$G$2:$G$83,8,ACCOUNTS!$C$2:$C$83,"CHECKING") -> 2 | D13: =B13+C13 -> 5
A14: Harbor Branch | B14: =COUNTIFS(ACCOUNTS!$G$2:$G$83,9,ACCOUNTS!$C$2:$C$83,"SAVINGS") -> 3 | C14: =COUNTIFS(ACCOUNTS!$G$2:$G$83,9,ACCOUNTS!$C$2:$C$83,"CHECKING") -> 2 | D14: =B14+C14 -> 5
A15: Lakeside Branch | B15: =COUNTIFS(ACCOUNTS!$G$2:$G$83,10,ACCOUNTS!$C$2:$C$83,"SAVINGS") -> 2 | C15: =COUNTIFS(ACCOUNTS!$G$2:$G$83,10,ACCOUNTS!$C$2:$C$83,"CHECKING") -> 4 | D15: =B15+C15 -> 6
A16: Bay Branch | B16: =COUNTIFS(ACCOUNTS!$G$2:$G$83,11,ACCOUNTS!$C$2:$C$83,"SAVINGS") -> 3 | C16: =COUNTIFS(ACCOUNTS!$G$2:$G$83,11,ACCOUNTS!$C$2:$C$83,"CHECKING") -> 2 | D16: =B16+C16 -> 5
A17: Riverside Branch | B17: =COUNTIFS(ACCOUNTS!$G$2:$G$83,12,ACCOUNTS!$C$2:$C$83,"SAVINGS") -> 3 | C17: =COUNTIFS(ACCOUNTS!$G$2:$G$83,12,ACCOUNTS!$C$2:$C$83,"CHECKING") -> 1 | D17: =B17+C17 -> 4
A18: Metro Branch | B18: =COUNTIFS(ACCOUNTS!$G$2:$G$83,13,ACCOUNTS!$C$2:$C$83,"SAVINGS") -> 1 | C18: =COUNTIFS(ACCOUNTS!$G$2:$G$83,13,ACCOUNTS!$C$2:$C$83,"CHECKING") -> 3 | D18: =B18+C18 -> 4
A19: Midtown Branch | B19: =COUNTIFS(ACCOUNTS!$G$2:$G$83,14,ACCOUNTS!$C$2:$C$83,"SAVINGS") -> 3 | C19: =COUNTIFS(ACCOUNTS!$G$2:$G$83,14,ACCOUNTS!$C$2:$C$83,"CHECKING") -> 1 | D19: =B19+C19 -> 4
A20: Garden Branch | B20: =COUNTIFS(ACCOUNTS!$G$2:$G$83,15,ACCOUNTS!$C$2:$C$83,"SAVINGS") -> 2 | C20: =COUNTIFS(ACCOUNTS!$G$2:$G$83,15,ACCOUNTS!$C$2:$C$83,"CHECKING") -> 2 | D20: =B20+C20 -> 4
A21: Strip Branch | B21: =COUNTIFS(ACCOUNTS!$G$2:$G$83,30,ACCOUNTS!$C$2:$C$83,"SAVINGS") -> 1 | C21: =COUNTIFS(ACCOUNTS!$G$2:$G$83,30,ACCOUNTS!$C$2:$C$83,"CHECKING") -> 1 | D21: =B21+C21 -> 2
A22: Broadway Branch | B22: =COUNTIFS(ACCOUNTS!$G$2:$G$83,31,ACCOUNTS!$C$2:$C$83,"SAVINGS") -> 1 | C22: =COUNTIFS(ACCOUNTS!$G$2:$G$83,31,ACCOUNTS!$C$2:$C$83,"CHECKING") -> 0 | D22: =B22+C22 -> 1
A23: Sixth Street Branch | B23: =COUNTIFS(ACCOUNTS!$G$2:$G$83,32,ACCOUNTS!$C$2:$C$83,"SAVINGS") -> 1 | C23: =COUNTIFS(ACCOUNTS!$G$2:$G$83,32,ACCOUNTS!$C$2:$C$83,"CHECKING") -> 1 | D23: =B23+C23 -> 2
A24: Gaslamp Branch | B24: =COUNTIFS(ACCOUNTS!$G$2:$G$83,33,ACCOUNTS!$C$2:$C$83,"SAVINGS") -> 1 | C24: =COUNTIFS(ACCOUNTS!$G$2:$G$83,33,ACCOUNTS!$C$2:$C$83,"CHECKING") -> 0 | D24: =B24+C24 -> 1
A25: Midtown Branch | B25: =COUNTIFS(ACCOUNTS!$G$2:$G$83,34,ACCOUNTS!$C$2:$C$83,"SAVINGS") -> 1 | C25: =COUNTIFS(ACCOUNTS!$G$2:$G$83,34,ACCOUNTS!$C$2:$C$83,"CHECKING") -> 1 | D25: =B25+C25 -> 2
A26: Uptown Branch | B26: =COUNTIFS(ACCOUNTS!$G$2:$G$83,35,ACCOUNTS!$C$2:$C$83,"SAVINGS") -> 1 | C26: =COUNTIFS(ACCOUNTS!$G$2:$G$83,35,ACCOUNTS!$C$2:$C$83,"CHECKING") -> 0 | D26: =B26+C26 -> 1
A27: Gateway Branch | B27: =COUNTIFS(ACCOUNTS!$G$2:$G$83,36,ACCOUNTS!$C$2:$C$83,"SAVINGS") -> 0 | C27: =COUNTIFS(ACCOUNTS!$G$2:$G$83,36,ACCOUNTS!$C$2:$C$83,"CHECKING") -> 1 | D27: =B27+C27 -> 1
A28: Inner Harbor Branch | B28: =COUNTIFS(ACCOUNTS!$G$2:$G$83,37,ACCOUNTS!$C$2:$C$83,"SAVINGS") -> 1 | C28: =COUNTIFS(ACCOUNTS!$G$2:$G$83,37,ACCOUNTS!$C$2:$C$83,"CHECKING") -> 0 | D28: =B28+C28 -> 1
A29: Research Branch | B29: =COUNTIFS(ACCOUNTS!$G$2:$G$83,38,ACCOUNTS!$C$2:$C$83,"SAVINGS") -> 1 | C29: =COUNTIFS(ACCOUNTS!$G$2:$G$83,38,ACCOUNTS!$C$2:$C$83,"CHECKING") -> 1 | D29: =B29+C29 -> 2
A30: Uptown Branch | B30: =COUNTIFS(ACCOUNTS!$G$2:$G$83,39,ACCOUNTS!$C$2:$C$83,"SAVINGS") -> 1 | C30: =COUNTIFS(ACCOUNTS!$G$2:$G$83,39,ACCOUNTS!$C$2:$C$83,"CHECKING") -> 0 | D30: =B30+C30 -> 1
A31: Grand Total | B31: =SUM(B6:B30) -> 45 | C31: =SUM(C6:C30) -> 37 | D31: =SUM(D6:D30) -> 82
A33: Pivot 2 — Loans by Type × Status
A34: Loan Type | B34: ACTIVE | C34: PAID | D34: Total Loans | E34: Total Amount
A35: HOME | B35: =COUNTIFS(LOANS!$C$2:$C$61,A35,LOANS!$H$2:$H$61,"ACTIVE") -> 17 | C35: =COUNTIFS(LOANS!$C$2:$C$61,A35,LOANS!$H$2:$H$61,"PAID") -> 0 | D35: =B35+C35 -> 17 | E35: =SUMIF(LOANS!$C$2:$C$61,A35,LOANS!$D$2:$D$61) -> 3710000
A36: BUSINESS | B36: =COUNTIFS(LOANS!$C$2:$C$61,A36,LOANS!$H$2:$H$61,"ACTIVE") -> 9 | C36: =COUNTIFS(LOANS!$C$2:$C$61,A36,LOANS!$H$2:$H$61,"PAID") -> 0 | D36: =B36+C36 -> 9 | E36: =SUMIF(LOANS!$C$2:$C$61,A36,LOANS!$D$2:$D$61) -> 2280000
A37: CAR | B37: =COUNTIFS(LOANS!$C$2:$C$61,A37,LOANS!$H$2:$H$61,"ACTIVE") -> 16 | C37: =COUNTIFS(LOANS!$C$2:$C$61,A37,LOANS!$H$2:$H$61,"PAID") -> 2 | D37: =B37+C37 -> 18 | E37: =SUMIF(LOANS!$C$2:$C$61,A37,LOANS!$D$2:$D$61) -> 290000
A38: PERSONAL | B38: =COUNTIFS(LOANS!$C$2:$C$61,A38,LOANS!$H$2:$H$61,"ACTIVE") -> 10 | C38: =COUNTIFS(LOANS!$C$2:$C$61,A38,LOANS!$H$2:$H$61,"PAID") -> 6 | D38: =B38+C38 -> 16 | E38: =SUMIF(LOANS!$C$2:$C$61,A38,LOANS!$D$2:$D$61) -> 94000
A39: Grand Total | B39: =SUM(B35:B38) -> 52 | C39: =SUM(C35:C38) -> 8 | D39: =SUM(D35:D38) -> 60 | E39: =SUM(E35:E38) -> 6374000
A41: Pivot 3 — Transaction Amount by Month × Type
A42: Month | B42: DEPOSIT | C42: WITHDRAWAL | D42: TRANSFER | E42: Total
A43: 2024-01 | B43: =SUMIFS(TRANSACTIONS!$D$2:$D$81,TRANSACTIONS!$E$2:$E$81,">="&DATE(2024,1,1),TRANSACTIONS!$E$2:$E$81,"<"&DATE(2024,2,1),TRANSACTIONS!$C$2:$C$81,"DEPOSIT") -> 17800 | C43: =SUMIFS(TRANSACTIONS!$D$2:$D$81,TRANSACTIONS!$E$2:$E$81,">="&DATE(2024,1,1),TRANSACTIONS!$E$2:$E$81,"<"&DATE(2024,2,1),TRANSACTIONS!$C$2:$C$81,"WITHDRAWAL") -> 2200 | D43: =SUMIFS(TRANSACTIONS!$D$2:$D$81,TRANSACTIONS!$E$2:$E$81,">="&DATE(2024,1,1),TRANSACTIONS!$E$2:$E$81,"<"&DATE(2024,2,1),TRANSACTIONS!$C$2:$C$81,"TRANSFER") -> 0 | E43: =B43+C43+D43 -> 20000
...

Sheet Data_Quality
A1: Data Quality • Validation Report
A2: Every check is a live formula. PASS/FAIL recalculates if the raw data changes.
A4: A. Table Inventory & Primary-Key Duplicate Check
A5: Table | B5: Primary Key | C5: Rows | D5: Distinct Keys | E5: Duplicate Keys | F5: Status
A6: BRANCHES | B6: branch_id | C6: =COUNTA(BRANCHES!$A$2:$A$61) -> 60 | D6: =SUMPRODUCT(1/COUNTIF(BRANCHES!$A$2:$A$61,BRANCHES!$A$2:$A$61)) -> 60 | E6: =C6-D6 -> 0 | F6: =IF(E6=0,"PASS","FAIL") -> PASS
A7: CUSTOMERS | B7: customer_id | C7: =COUNTA(CUSTOMERS!$A$2:$A$61) -> 60 | D7: =SUMPRODUCT(1/COUNTIF(CUSTOMERS!$A$2:$A$61,CUSTOMERS!$A$2:$A$61)) -> 60 | E7: =C7-D7 -> 0 | F7: =IF(E7=0,"PASS","FAIL") -> PASS
A8: ACCOUNTS | B8: account_id | C8: =COUNTA(ACCOUNTS!$A$2:$A$83) -> 82 | D8: =SUMPRODUCT(1/COUNTIF(ACCOUNTS!$A$2:$A$83,ACCOUNTS!$A$2:$A$83)) -> 82 | E8: =C8-D8 -> 0 | F8: =IF(E8=0,"PASS","FAIL") -> PASS
A9: TRANSACTIONS | B9: transaction_id | C9: =COUNTA(TRANSACTIONS!$A$2:$A$81) -> 80 | D9: =SUMPRODUCT(1/COUNTIF(TRANSACTIONS!$A$2:$A$81,TRANSACTIONS!$A$2:$A$81)) -> 80 | E9: =C9-D9 -> 0 | F9: =IF(E9=0,"PASS","FAIL") -> PASS
A10: LOANS | B10: loan_id | C10: =COUNTA(LOANS!$A$2:$A$61) -> 60 | D10: =SUMPRODUCT(1/COUNTIF(LOANS!$A$2:$A$61,LOANS!$A$2:$A$61)) -> 60 | E10: =C10-D10 -> 0 | F10: =IF(E10=0,"PASS","FAIL") -> PASS
A11: EMPLOYEES | B11: employee_id | C11: =COUNTA(EMPLOYEES!$A$2:$A$61) -> 60 | D11: =SUMPRODUCT(1/COUNTIF(EMPLOYEES!$A$2:$A$61,EMPLOYEES!$A$2:$A$61)) -> 60 | E11: =C11-D11 -> 0 | F11: =IF(E11=0,"PASS","FAIL") -> PASS
A12: CARDS | B12: card_id | C12: =COUNTA(CARDS!$A$2:$A$61) -> 60 | D12: =SUMPRODUCT(1/COUNTIF(CARDS!$A$2:$A$61,CARDS!$A$2:$A$61)) -> 60 | E12: =C12-D12 -> 0 | F12: =IF(E12=0,"PASS","FAIL") -> PASS
A13: TRANSFERS | B13: transfer_id | C13: =COUNTA(TRANSFERS!$A$2:$A$61) -> 60 | D13: =SUMPRODUCT(1/COUNTIF(TRANSFERS!$A$2:$A$61,TRANSFERS!$A$2:$A$61)) -> 60 | E13: =C13-D13 -> 0 | F13: =IF(E13=0,"PASS","FAIL") -> PASS
A14: BENEFICIARIES | B14: beneficiary_id | C14: =COUNTA(BENEFICIARIES!$A$2:$A$61) -> 60 | D14: =SUMPRODUCT(1/COUNTIF(BENEFICIARIES!$A$2:$A$61,BENEFICIARIES!$A$2:$A$61)) -> 60 | E14: =C14-D14 -> 0 | F14: =IF(E14=0,"PASS","FAIL") -> PASS
A15: FEES | B15: fee_id | C15: =COUNTA(FEES!$A$2:$A$61) -> 60 | D15: =SUMPRODUCT(1/COUNTIF(FEES!$A$2:$A$61,FEES!$A$2:$A$61)) -> 60 | E15: =C15-D15 -> 0 | F15: =IF(E15=0,"PASS","FAIL") -> PASS
A16: LOAN_PAYMENTS | B16: payment_id | C16: =COUNTA(LOAN_PAYMENTS!$A$2:$A$61) -> 60 | D16: =SUMPRODUCT(1/COUNTIF(LOAN_PAYMENTS!$A$2:$A$61,LOAN_PAYMENTS!$A$2:$A$61)) -> 60 | E16: =C16-D16 -> 0 | F16: =IF(E16=0,"PASS","FAIL") -> PASS
A17: STANDING_ORDERS | B17: order_id | C17: =COUNTA(STANDING_ORDERS!$A$2:$A$61) -> 60 | D17: =SUMPRODUCT(1/COUNTIF(STANDING_ORDERS!$A$2:$A$61,STANDING_ORDERS!$A$2:$A$61)) -> 60 | E17: =C17-D17 -> 0 | F17: =IF(E17=0,"PASS","FAIL") -> PASS
A18: ATM_MACHINES | B18: atm_id | C18: =COUNTA(ATM_MACHINES!$A$2:$A$61) -> 60 | D18: =SUMPRODUCT(1/COUNTIF(ATM_MACHINES!$A$2:$A$61,ATM_MACHINES!$A$2:$A$61)) -> 60 | E18: =C18-D18 -> 0 | F18: =IF(E18=0,"PASS","FAIL") -> PASS
A19: AUDIT_LOG | B19: log_id | C19: =COUNTA(AUDIT_LOG!$A$2:$A$61) -> 60 | D19: =SUMPRODUCT(1/COUNTIF(AUDIT_LOG!$A$2:$A$61,AUDIT_LOG!$A$2:$A$61)) -> 60 | E19: =C19-D19 -> 0 | F19: =IF(E19=0,"PASS","FAIL") -> PASS
A21: B. Missing-Value (NULL / blank) Checks
A22: Table.Column | B22: Blanks | C22: Expected Nulls? | D22: Status
A23: CUSTOMERS.email | B23: =COUNTBLANK(CUSTOMERS!$A$2:$A$61) -> 0 | C23: No | D23: =IF(B23=0,"PASS","FAIL") -> PASS
A24: CUSTOMERS.city | B24: =COUNTBLANK(CUSTOMERS!$F$2:$F$61) -> 0 | C24: No | D24: =IF(B24=0,"PASS","FAIL") -> PASS
A25: ACCOUNTS.balance | B25: =COUNTBLANK(ACCOUNTS!$D$2:$D$83) -> 0 | C25: No | D25: =IF(B25=0,"PASS","FAIL") -> PASS
A26: ACCOUNTS.status | B26: =COUNTBLANK(ACCOUNTS!$F$2:$F$83) -> 0 | C26: No | D26: =IF(B26=0,"PASS","FAIL") -> PASS
A27: TRANSACTIONS.amount | B27: =COUNTBLANK(TRANSACTIONS!$D$2:$D$81) -> 0 | C27: No | D27: =IF(B27=0,"PASS","FAIL") -> PASS
A28: LOANS.amount | B28: =COUNTBLANK(LOANS!$D$2:$D$61) -> 0 | C28: No | D28: =IF(B28=0,"PASS","FAIL") -> PASS
A29: LOANS.status | B29: =COUNTBLANK(LOANS!$H$2:$H$61) -> 0 | C29: No | D29: =IF(B29=0,"PASS","FAIL") -> PASS
A30: EMPLOYEES.branch_id | B30: =COUNTBLANK(EMPLOYEES!$F$2:$F$61) -> 0 | C30: No | D30: =IF(B30=0,"PASS","FAIL") -> PASS
A31: EMPLOYEES.manager_id | B31: =COUNTBLANK(EMPLOYEES!$H$2:$H$61) -> 25 | C31: Yes — branch managers have none | D31: REVIEW
A32: CARDS.status | B32: =COUNTBLANK(CARDS!$F$2:$F$61) -> 0 | C32: No | D32: =IF(B32=0,"PASS","FAIL") -> PASS
A33: CARDS.credit_limit | B33: =COUNTBLANK(CARDS!$G$2:$G$61) -> 38 | C33: Yes — debit cards have none | D33: REVIEW
A35: C. Referential Integrity (orphan child rows)
A36: Child → Parent | B36: Foreign Key | C36: Orphans | D36: Status
A37: ACCOUNTS → CUSTOMERS | B37: customer_id | C37: =SUMPRODUCT(--(COUNTIF(CUSTOMERS!$A$2:$A$61,ACCOUNTS!$B$2:$B$83)=0)) -> 0 | D37: =IF(C37=0,"PASS","FAIL") -> PASS
A38: TRANSACTIONS → ACCOUNTS | B38: account_id | C38: =SUMPRODUCT(--(COUNTIF(ACCOUNTS!$A$2:$A$83,TRANSACTIONS!$B$2:$B$81)=0)) -> 0 | D38: =IF(C38=0,"PASS","FAIL") -> PASS
A39: LOANS → CUSTOMERS | B39: customer_id | C39: =SUMPRODUCT(--(COUNTIF(CUSTOMERS!$A$2:$A$61,LOANS!$B$2:$B$61)=0)) -> 0 | D39: =IF(C39=0,"PASS","FAIL") -> PASS
A40: CARDS → ACCOUNTS | B40: account_id | C40: =SUMPRODUCT(--(COUNTIF(ACCOUNTS!$A$2:$A$83,CARDS!$B$2:$B$61)=0)) -> 0 | D40: =IF(C40=0,"PASS","FAIL") -> PASS
A41: CUSTOMERS → BRANCHES | B41: branch_id | C41: =SUMPRODUCT(--(COUNTIF(BRANCHES!$A$2:$A$61,CUSTOMERS!$H$2:$H$61)=0)) -> 0 | D41: =IF(C41=0,"PASS","FAIL") -> PASS
A42: EMPLOYEES → BRANCHES | B42: branch_id | C42: =SUMPRODUCT(--(COUNTIF(BRANCHES!$A$2:$A$61,EMPLOYEES!$F$2:$F$61)=0)) -> 0 | D42: =IF(C42=0,"PASS","FAIL") -> PASS
A44: D. Value-Domain Validation (values outside allowed set)
...

Sheet BRANCHES
A1: branch_id | B1: branch_name | C1: city | D1: phone
A2: 1 | B2: Main Branch | C2: New York | D2: 212-000-0001
A3: 2 | B3: Downtown Branch | C3: New York | D3: 212-000-0002
A4: 3 | B4: West Branch | C4: Los Angeles | D4: 310-000-0001
A5: 4 | B5: North Branch | C5: Chicago | D5: 312-000-0001
A6: 5 | B6: East Branch | C6: Houston | D6: 713-000-0001
A7: 6 | B7: South Branch | C7: Miami | D7: 305-000-0001
A8: 7 | B8: Central Branch | C8: Dallas | D8: 214-000-0001
A9: 8 | B9: NorthWest Branch | C9: Seattle | D9: 206-000-0001
A10: 9 | B10: Harbor Branch | C10: Boston | D10: 617-000-0001
A11: 10 | B11: Lakeside Branch | C11: Denver | D11: 720-000-0001
A12: 11 | B12: Bay Branch | C12: San Francisco | D12: 415-000-0001
A13: 12 | B13: Riverside Branch | C13: Phoenix | D13: 602-000-0001
... A61: 60 | B61: Brookside Branch | C61: Tulsa | D61: 918-000-0001

Sheet CUSTOMERS
A1: customer_id | B1: first_name | C1: last_name | D1: email | E1: phone | F1: city | G1: join_date | H1: branch_id
A2: 1 | B2: Alice | C2: Johnson | D2: alice@email.com | E2: 555-1001 | F2: New York | G2: 43845 | H2: 1
A3: 2 | B3: Bob | C3: Smith | D3: bob@email.com | E3: 555-1002 | F3: New York | G3: 43546 | H3: 2
A4: 3 | B4: Carol | C4: Davis | D4: carol@email.com | E4: 555-1003 | F4: Los Angeles | G4: 44387 | H4: 3
A5: 4 | B5: David | C5: Wilson | D5: david@email.com | E5: 555-1004 | F5: Chicago | G5: 43409 | H5: 4
A6: 5 | B6: Emma | C6: Brown | D6: emma@email.com | E6: 555-1005 | F6: Houston | G6: 44620 | H6: 5
A7: 6 | B7: Frank | C7: Taylor | D7: frank@email.com | E7: 555-1006 | F7: New York | G7: 43996 | H7: 1
A8: 7 | B8: Grace | C8: Anderson | D8: grace@email.com | E8: 555-1007 | F8: Los Angeles | G8: 44469 | H8: 3
A9: 8 | B9: Henry | C9: Martinez | D9: henry@email.com | E9: 555-1008 | F9: Chicago | G9: 43800 | H9: 4
A10: 9 | B10: Irene | C10: Garcia | D10: irene@email.com | E10: 555-1009 | F10: Houston | G10: 44946 | H10: 5
A11: 10 | B11: James | C11: Lee | D11: james@email.com | E11: 555-1010 | F11: New York | G11: 42965 | H11: 2
A12: 11 | B12: Liam | C12: Thompson | D12: liam@email.com | E12: 555-2001 | F12: Miami | G12: 44270 | H12: 6
A13: 12 | B13: Sophia | C13: Walker | D13: sophia@email.com | E13: 555-2002 | F13: Miami | G13: 44063 | H13: 6
... A61: 60 | B61: Nora | C61: Russell | D61: nora@email.com | E61: 555-3010 | F61: Charlotte | G61: 44538 | H61: 39

Sheet ACCOUNTS
A1: account_id | B1: customer_id | C1: account_type | D1: balance | E1: open_date | F1: status | G1: branch_id | H1: branch_name | I1: city
A2: 101 | B2: 1 | C2: SAVINGS | D2: 15000 | E2: 43845 | F2: ACTIVE | G2: =INDEX(CUSTOMERS!$H$2:$H$61,MATCH($B2,CUSTOMERS!$A$2:$A$61,0)) -> 1 | H2: =INDEX(BRANCHES!$B$2:$B$61,MATCH($G2,BRANCHES!$A$2:$A$61,0)) -> Main Branch | I2: =INDEX(BRANCHES!$C$2:$C$61,MATCH($G2,BRANCHES!$A$2:$A$61,0)) -> New York
A3: 102 | B3: 1 | C3: CHECKING | D3: 3200 | E3: 43891 | F3: ACTIVE | G3: =INDEX(CUSTOMERS!$H$2:$H$61,MATCH($B3,CUSTOMERS!$A$2:$A$61,0)) -> 1 | H3: =INDEX(BRANCHES!$B$2:$B$61,MATCH($G3,BRANCHES!$A$2:$A$61,0)) -> Main Branch | I3: =INDEX(BRANCHES!$C$2:$C$61,MATCH($G3,BRANCHES!$A$2:$A$61,0)) -> New York
A4: 103 | B4: 2 | C4: SAVINGS | D4: 8500 | E4: 43546 | F4: ACTIVE | G4: =INDEX(CUSTOMERS!$H$2:$H$61,MATCH($B4,CUSTOMERS!$A$2:$A$61,0)) -> 2 | H4: =INDEX(BRANCHES!$B$2:$B$61,MATCH($G4,BRANCHES!$A$2:$A$61,0)) -> Downtown Branch | I4: =INDEX(BRANCHES!$C$2:$C$61,MATCH($G4,BRANCHES!$A$2:$A$61,0)) -> New York
A5: 104 | B5: 3 | C5: CHECKING | D5: 1200 | E5: 44387 | F5: ACTIVE | G5: =INDEX(CUSTOMERS!$H$2:$H$61,MATCH($B5,CUSTOMERS!$A$2:$A$61,0)) -> 3 | H5: =INDEX(BRANCHES!$B$2:$B$61,MATCH($G5,BRANCHES!$A$2:$A$61,0)) -> West Branch | I5: =INDEX(BRANCHES!$C$2:$C$61,MATCH($G5,BRANCHES!$A$2:$A$61,0)) -> Los Angeles
A6: 105 | B6: 4 | C6: SAVINGS | D6: 50000 | E6: 43409 | F6: ACTIVE | G6: =INDEX(CUSTOMERS!$H$2:$H$61,MATCH($B6,CUSTOMERS!$A$2:$A$61,0)) -> 4 | H6: =INDEX(BRANCHES!$B$2:$B$61,MATCH($G6,BRANCHES!$A$2:$A$61,0)) -> North Branch | I6: =INDEX(BRANCHES!$C$2:$C$61,MATCH($G6,BRANCHES!$A$2:$A$61,0)) -> Chicago
A7: 106 | B7: 5 | C7: CHECKING | D7: 750 | E7: 44620 | F7: ACTIVE | G7: =INDEX(CUSTOMERS!$H$2:$H$61,MATCH($B7,CUSTOMERS!$A$2:$A$61,0)) -> 5 | H7: =INDEX(BRANCHES!$B$2:$B$61,MATCH($G7,BRANCHES!$A$2:$A$61,0)) -> East Branch | I7: =INDEX(BRANCHES!$C$2:$C$61,MATCH($G7,BRANCHES!$A$2:$A$61,0)) -> Houston
A8: 107 | B8: 6 | C8: SAVINGS | D8: 22000 | E8: 43996 | F8: ACTIVE | G8: =INDEX(CUSTOMERS!$H$2:$H$61,MATCH($B8,CUSTOMERS!$A$2:$A$61,0)) -> 1 | H8: =INDEX(BRANCHES!$B$2:$B$61,MATCH($G8,BRANCHES!$A$2:$A$61,0)) -> Main Branch | I8: =INDEX(BRANCHES!$C$2:$C$61,MATCH($G8,BRANCHES!$A$2:$A$61,0)) -> New York
A9: 108 | B9: 7 | C9: CHECKING | D9: 4300 | E9: 44469 | F9: ACTIVE | G9: =INDEX(CUSTOMERS!$H$2:$H$61,MATCH($B9,CUSTOMERS!$A$2:$A$61,0)) -> 3 | H9: =INDEX(BRANCHES!$B$2:$B$61,MATCH($G9,BRANCHES!$A$2:$A$61,0)) -> West Branch | I9: =INDEX(BRANCHES!$C$2:$C$61,MATCH($G9,BRANCHES!$A$2:$A$61,0)) -> Los Angeles
A10: 109 | B10: 8 | C10: SAVINGS | D10: 9800 | E10: 43800 | F10: ACTIVE | G10: =INDEX(CUSTOMERS!$H$2:$H$61,MATCH($B10,CUSTOMERS!$A$2:$A$61,0)) -> 4 | H10: =INDEX(BRANCHES!$B$2:$B$61,MATCH($G10,BRANCHES!$A$2:$A$61,0)) -> North Branch | I10: =INDEX(BRANCHES!$C$2:$C$61,MATCH($G10,BRANCHES!$A$2:$A$61,0)) -> Chicago
A11: 110 | B11: 9 | C11: CHECKING | D11: 300 | E11: 44946 | F11: ACTIVE | G11: =INDEX(CUSTOMERS!$H$2:$H$61,MATCH($B11,CUSTOMERS!$A$2:$A$61,0)) -> 5 | H11: =INDEX(BRANCHES!$B$2:$B$61,MATCH($G11,BRANCHES!$A$2:$A$61,0)) -> East Branch | I11: =INDEX(BRANCHES!$C$2:$C$61,MATCH($G11,BRANCHES!$A$2:$A$61,0)) -> Houston
A12: 111 | B12: 10 | C12: SAVINGS | D12: 67000 | E12: 42965 | F12: ACTIVE | G12: =INDEX(CUSTOMERS!$H$2:$H$61,MATCH($B12,CUSTOMERS!$A$2:$A$61,0)) -> 2 | H12: =INDEX(BRANCHES!$B$2:$B$61,MATCH($G12,BRANCHES!$A$2:$A$61,0)) -> Downtown Branch | I12: =INDEX(BRANCHES!$C$2:$C$61,MATCH($G12,BRANCHES!$A$2:$A$61,0)) -> New York
A13: 112 | B13: 10 | C13: CHECKING | D13: 5500 | E13: 43110 | F13: ACTIVE | G13: =INDEX(CUSTOMERS!$H$2:$H$61,MATCH($B13,CUSTOMERS!$A$2:$A$61,0)) -> 2 | H13: =INDEX(BRANCHES!$B$2:$B$61,MATCH($G13,BRANCHES!$A$2:$A$61,0)) -> Downtown Branch | I13: =INDEX(BRANCHES!$C$2:$C$61,MATCH($G13,BRANCHES!$A$2:$A$61,0)) -> New York
... A83: 182 | B83: 60 | C83: SAVINGS | D83: 8700 | E83: 44538 | F83: ACTIVE | G83: =INDEX(CUSTOMERS!$H$2:$H$61,MATCH($B83,CUSTOMERS!$A$2:$A$61,0)) -> 39 | H83: =INDEX(BRANCHES!$B$2:$B$61,MATCH($G83,BRANCHES!$A$2:$A$61,0)) -> Uptown Branch | I83: =INDEX(BRANCHES!$C$2:$C$61,MATCH($G83,BRANCHES!$A$2:$A$61,0)) -> Charlotte

Sheet TRANSACTIONS
A1: transaction_id | B1: account_id | C1: trans_type | D1: amount | E1: trans_date | F1: description
A2: 1001 | B2: 101 | C2: DEPOSIT | D2: 5000 | E2: 45296 | F2: Salary deposit
A3: 1002 | B3: 101 | C3: WITHDRAWAL | D3: 1200 | E3: 45301 | F3: Rent payment
A4: 1003 | B4: 102 | C4: DEPOSIT | D4: 800 | E4: 45303 | F4: Freelance payment
A5: 1004 | B5: 103 | C5: DEPOSIT | D5: 2000 | E5: 45306 | F5: Salary deposit
A6: 1005 | B6: 103 | C6: WITHDRAWAL | D6: 500 | E6: 45309 | F6: Grocery shopping
A7: 1006 | B7: 104 | C7: WITHDRAWAL | D7: 300 | E7: 45311 | F7: Utility bill
A8: 1007 | B8: 105 | C8: DEPOSIT | D8: 10000 | E8: 45313 | F8: Business revenue
A9: 1008 | B9: 106 | C9: WITHDRAWAL | D9: 200 | E9: 45316 | F9: ATM withdrawal
A10: 1009 | B10: 107 | C10: DEPOSIT | D10: 3000 | E10: 45323 | F10: Salary deposit
A11: 1010 | B11: 108 | C11: TRANSFER | D11: 1500 | E11: 45327 | F11: Transfer to savings
A12: 1011 | B12: 109 | C12: DEPOSIT | D12: 4500 | E12: 45332 | F12: Salary deposit
A13: 1012 | B13: 110 | C13: WITHDRAWAL | D13: 100 | E13: 45334 | F13: ATM withdrawal
... A81: 1080 | B81: 182 | C81: WITHDRAWAL | D81: 300 | E81: 45516 | F81: ATM withdrawal

Sheet LOANS
A1: loan_id | B1: customer_id | C1: loan_type | D1: amount | E1: interest_rate | F1: start_date | G1: end_date | H1: status | I1: branch_id | J1: branch_name
A2: 201 | B2: 1 | C2: HOME | D2: 200000 | E2: 3.5 | F2: 43862 | G2: 54820 | H2: ACTIVE | I2: =INDEX(CUSTOMERS!$H$2:$H$61,MATCH($B2,CUSTOMERS!$A$2:$A$61,0)) -> 1 | J2: =INDEX(BRANCHES!$B$2:$B$61,MATCH($I2,BRANCHES!$A$2:$A$61,0)) -> Main Branch
A3: 202 | B3: 2 | C3: CAR | D3: 15000 | E3: 5.2 | F3: 44362 | G3: 46188 | H3: ACTIVE | I3: =INDEX(CUSTOMERS!$H$2:$H$61,MATCH($B3,CUSTOMERS!$A$2:$A$61,0)) -> 2 | J3: =INDEX(BRANCHES!$B$2:$B$61,MATCH($I3,BRANCHES!$A$2:$A$61,0)) -> Downtown Branch
A4: 203 | B4: 3 | C4: PERSONAL | D4: 5000 | E4: 7.8 | F4: 44571 | G4: 45667 | H4: ACTIVE | I4: =INDEX(CUSTOMERS!$H$2:$H$61,MATCH($B4,CUSTOMERS!$A$2:$A$61,0)) -> 3 | J4: =INDEX(BRANCHES!$B$2:$B$61,MATCH($I4,BRANCHES!$A$2:$A$61,0)) -> West Branch
A5: 204 | B5: 4 | C5: BUSINESS | D5: 80000 | E5: 4.1 | F5: 43544 | G5: 47197 | H5: ACTIVE | I5: =INDEX(CUSTOMERS!$H$2:$H$61,MATCH($B5,CUSTOMERS!$A$2:$A$61,0)) -> 4 | J5: =INDEX(BRANCHES!$B$2:$B$61,MATCH($I5,BRANCHES!$A$2:$A$61,0)) -> North Branch
A6: 205 | B6: 5 | C6: CAR | D6: 12000 | E6: 6 | F6: 44682 | G6: 46508 | H6: ACTIVE | I6: =INDEX(CUSTOMERS!$H$2:$H$61,MATCH($B6,CUSTOMERS!$A$2:$A$61,0)) -> 5 | J6: =INDEX(BRANCHES!$B$2:$B$61,MATCH($I6,BRANCHES!$A$2:$A$61,0)) -> East Branch
A7: 206 | B7: 6 | C7: PERSONAL | D7: 3000 | E7: 8.5 | F7: 44530 | G7: 45626 | H7: PAID | I7: =INDEX(CUSTOMERS!$H$2:$H$61,MATCH($B7,CUSTOMERS!$A$2:$A$61,0)) -> 1 | J7: =INDEX(BRANCHES!$B$2:$B$61,MATCH($I7,BRANCHES!$A$2:$A$61,0)) -> Main Branch
A8: 207 | B8: 8 | C8: HOME | D8: 150000 | E8: 3.75 | F8: 44027 | G8: 53158 | H8: ACTIVE | I8: =INDEX(CUSTOMERS!$H$2:$H$61,MATCH($B8,CUSTOMERS!$A$2:$A$61,0)) -> 4 | J8: =INDEX(BRANCHES!$B$2:$B$61,MATCH($I8,BRANCHES!$A$2:$A$61,0)) -> North Branch
A9: 208 | B9: 10 | C9: BUSINESS | D9: 100000 | E9: 3.9 | F9: 43344 | G9: 46997 | H9: ACTIVE | I9: =INDEX(CUSTOMERS!$H$2:$H$61,MATCH($B9,CUSTOMERS!$A$2:$A$61,0)) -> 2 | J9: =INDEX(BRANCHES!$B$2:$B$61,MATCH($I9,BRANCHES!$A$2:$A$61,0)) -> Downtown Branch
A10: 209 | B10: 11 | C10: HOME | D10: 180000 | E10: 3.6 | F10: 44287 | G10: 55244 | H10: ACTIVE | I10: =INDEX(CUSTOMERS!$H$2:$H$61,MATCH($B10,CUSTOMERS!$A$2:$A$61,0)) -> 6 | J10: =INDEX(BRANCHES!$B$2:$B$61,MATCH($I10,BRANCHES!$A$2:$A$61,0)) -> South Branch
A11: 210 | B11: 12 | C11: CAR | D11: 20000 | E11: 5.5 | F11: 44440 | G11: 46266 | H11: ACTIVE | I11: =INDEX(CUSTOMERS!$H$2:$H$61,MATCH($B11,CUSTOMERS!$A$2:$A$61,0)) -> 6 | J11: =INDEX(BRANCHES!$B$2:$B$61,MATCH($I11,BRANCHES!$A$2:$A$61,0)) -> South Branch
A12: 211 | B12: 13 | C12: BUSINESS | D12: 120000 | E12: 4.2 | F12: 43845 | G12: 47498 | H12: ACTIVE | I12: =INDEX(CUSTOMERS!$H$2:$H$61,MATCH($B12,CUSTOMERS!$A$2:$A$61,0)) -> 7 | J12: =INDEX(BRANCHES!$B$2:$B$61,MATCH($I12,BRANCHES!$A$2:$A$61,0)) -> Central Branch
A13: 212 | B13: 14 | C13: PERSONAL | D13: 8000 | E13: 8 | F13: 44593 | G13: 45689 | H13: ACTIVE | I13: =INDEX(CUSTOMERS!$H$2:$H$61,MATCH($B13,CUSTOMERS!$A$2:$A$61,0)) -> 7 | J13: =INDEX(BRANCHES!$B$2:$B$61,MATCH($I13,BRANCHES!$A$2:$A$61,0)) -> Central Branch
... A61: 260 | B61: 9 | C61: PERSONAL | D61: 3500 | E61: 8.7 | F61: 44958 | G61: 46054 | H61: ACTIVE | I61: =INDEX(CUSTOMERS!$H$2:$H$61,MATCH($B61,CUSTOMERS!$A$2:$A$61,0)) -> 5 | J61: =INDEX(BRANCHES!$B$2:$B$61,MATCH($I61,BRANCHES!$A$2:$A$61,0)) -> East Branch

Sheet EMPLOYEES
A1: employee_id | B1: first_name | C1: last_name | D1: job_title | E1: salary | F1: branch_id | G1: hire_date | H1: manager_id
A2: 301 | B2: Sarah | C2: Connor | D2: Branch Manager | E2: 85000 | F2: 1 | G2: 42073
A3: 302 | B3: Tom | C3: Harris | D3: Branch Manager | E3: 80000 | F3: 2 | G3: 42552
A4: 303 | B4: Linda | C4: White | D4: Branch Manager | E4: 78000 | F4: 3 | G4: 42750
A5: 304 | B5: Mark | C5: Evans | D5: Branch Manager | E5: 82000 | F5: 4 | G5: 41902
A6: 305 | B6: Nancy | C6: Clark | D6: Branch Manager | E6: 79000 | F6: 5 | G6: 42679
A7: 306 | B7: Paul | C7: Walker | D7: Loan Officer | E7: 55000 | F7: 1 | G7: 43159 | H7: 301
A8: 307 | B8: Quinn | C8: Adams | D8: Teller | E8: 38000 | F8: 1 | G8: 43992 | H8: 301
A9: 308 | B9: Rachel | C9: Brown | D9: Teller | E9: 37000 | F9: 2 | G9: 44270 | H9: 302
A10: 309 | B10: Steve | C10: Young | D10: Loan Officer | E10: 54000 | F10: 3 | G10: 43699 | H10: 303
A11: 310 | B11: Tina | C11: Scott | D11: Teller | E11: 36000 | F11: 4 | G11: 44571 | H11: 304
A12: 311 | B12: Uma | C12: James | D12: Branch Manager | E12: 83000 | F12: 6 | G12: 42156
A13: 312 | B13: Victor | C13: Hughes | D13: Branch Manager | E13: 81000 | F13: 7 | G13: 42444
A14: 313 | B14: Wendy | C14: Foster | D14: Branch Manager | E14: 79000 | F14: 8 | G14: 42979
A15: 314 | B15: Xavier | C15: Price | D15: Branch Manager | E15: 84000 | F15: 9 | G15: 41963
A16: 315 | B16: Yvonne | C16: Diaz | D16: Branch Manager | E16: 80000 | F16: 10 | G16: 42561
A17: 316 | B17: Zach | C17: Russell | D17: Branch Manager | E17: 86000 | F17: 11 | G17: 42009
